Workbook
Name Black: 코드목록!$A$32:$A$39
Name Blue: 코드목록!$A$17:$A$23
Name Green: 코드목록!$A$16
Name Pink: 코드목록!$A$2:$A$3
Name Red: 코드목록!$A$4:$A$8
Name White: 코드목록!$A$24:$A$31
Name Yellow: 코드목록!$A$9:$A$15

Sheet Dashboard
A1: 액상 잉크 Lot 추적 관리 시스템
A4: 📊 시트 구성
A5: • Spec_Binder: Binder 사양 기준 (PBHAv1.0, SBCT, SCRA)
A6: • Spec_Single_HEMA: HEMA 단일색 잉크 점도 기준 (21종)
A7: • Spec_Single_Silicone: Silicone 단일색 잉크 점도 기준 (18종)
A8: • 기준LAB: 착색력 기준 L*a*b* 값
A9: • 단일색_착색력: 착색력 측정 및 ΔE 자동 계산
A10: • 단일색_수입검사: 단일색 잉크 입고 검사 (Lot 자동생성, 판정 자동)
A11: • 바인더_제조_입고: Binder 제조/입고 관리 (Lot 자동, 판정 자동)
A12: • Lot규칙_단일색: Lot 번호 부여 규칙
A14: ✅ 자동화 기능
A15: • Lot 번호 자동 생성 (날짜 기반)
... A18: • Binder 추적 (단일색 잉크 → 사용 Binder Lot)

Sheet Spec_Binder
A1: 바인더명 | B1: 시험항목 | C1: 시험조건 | D1: 기준값 | E1: 하한 | F1: 상한 | G1: 비고 | H1: Lot부여규칙
A2: PBHAv1.0 | B2: UV 흡광도 | C2: 405 nm | D2: ≤ 0.40 | F2: 0.4 | G2: HEMA용, 외주(SM Tech) | H2: PCB+YYYYMMDD-##
A3: PBHAv1.0 | B3: 점도(cP) | C3: 25 °C | D3: 410 ± 50 | E3: 360 | F3: 460 | G3: Brookfield 기준 | H3: PCB+YYYYMMDD-##
A4: PBHBv1.0 | B4: UV 흡광도 | C4: 405 nm | D4: ≤ 0.10 | F4: 0.1 | G4: HEMA용, 내부/신규 | H4: BIH+YYYYMMDD-##
A5: PBHBv1.0 | B5: 점도(cP) | C5: 25 °C | D5: 320 ± 80 | E5: =320-80 -> 240 | F5: 400 | G5: Brookfield 기준 | H5: BIH+YYYYMMDD-##
A6: SBCT | B6: 점도(cP) | C6: 25 °C | D6: 170~220 | E6: 170 | F6: 220 | G6: Silicone Binder 1 | H6: SBCT+YYYYMMDD
A7: SCRA | B7: 점도(cP) | C7: 25 °C | D7: 50~70 | E7: 50 | F7: 70 | G7: Silicone Binder 2,3 | H7: SCRA+YYYYMMDD

Sheet Spec_Single_H&S
A1: 색상군 | B1: 제품코드 | C1: 점도기준(cP) | D1: 허용편차(±) | E1: 하한 | F1: 상한 | G1: BinderType
A2: Black | B2: PL-835-1 | C2: 75000 | D2: 15000 | E2: 60000 | F2: 90000 | G2: PBHAv1.0
A3: Black | B3: PL-835-1(H) | C3: 75000 | D3: 15000 | E3: 60000 | F3: 90000 | G3: PBHAv1.0
A4: Black | B4: PL-850 | C4: 75000 | D4: 15000 | E4: 60000 | F4: 90000 | G4: PBHAv1.0
A5: White | B5: PL-700-2 | C5: 19000 | D5: 5000 | E5: 14000 | F5: 24000 | G5: PBHAv1.0
A6: White | B6: PL-735 | C6: 16000 | D6: 5000 | E6: 11000 | F6: 21000 | G6: PBHAv1.0
A7: White | B7: NPL-700-2 | C7: 19000 | D7: 5000 | E7: 14000 | F7: 24000 | G7: PBHBv1.0
A8: White | B8: NPL-735 | C8: 16000 | D8: 5000 | E8: 11000 | F8: 21000 | G8: PBHBv1.0
A9: Blue | B9: PL-550 | C9: 35000 | D9: 5000 | E9: 30000 | F9: 40000 | G9: PBHAv1.0
A10: Blue | B10: PL-580 | C10: 63000 | D10: 10000 | E10: 53000 | F10: 73000 | G10: PBHAv1.0
A11: Blue | B11: PL-580-2 | C11: 63000 | D11: 10000 | E11: 53000 | F11: 73000 | G11: PBHAv1.0
A12: Blue | B12: PL-580-2(H) | C12: 63000 | D12: 10000 | E12: 53000 | F12: 73000 | G12: PBHAv1.0
A13: Blue | B13: NPL-580-2 | C13: 63000 | D13: 10000 | E13: 53000 | F13: 73000 | G13: PBHBv1.0
... A41: Red | B41: NSL-150 | C41: 36000 | D41: 5000 | E41: 31000 | F41: 41000 | G41: SCRA

Sheet 기준LAB
A1: 제품코드 | B1: 기준_L* | C1: 기준_a* | D1: 기준_b* | E1: 기준출처

Sheet 코드목록
A1: 제품코드
A2: PL-135
A3: NPL-135
A4: PL-150-2
A5: NPL-150-2
A6: SL-150
A7: SL-150-1
A8: NSL-150
A9: PL-345-2
A10: PL-345-3
A11: NPL-345-2
A12: NPL-345-3
... A39: NSL-850

Sheet Lot규칙_단일색
A1: 설명 | B1: 값
A2: 형식 | B2: PL/NPL + (색상코드) + YYMMDD + 2자리 일련번호
A3: 색상→코드 매핑 | B3: Black=B, White=W, Blue=U, Green=G, Yellow=Y, Red=R, Pink=P
A4: 예시(PL-835-1, Black, 2025-04-15) | B4: PLB25041501
A5: 예시(NPL-835-1, Black, 2025-04-15) | B5: NPLB25041501
A6: Silicone 형식 | B6: SL + (색상코드: B/W/U/G/Y/R/P) + YYMMDD + 2자리 일련번호
A7: 예시(SL-850, Black, 2025-10-24) | B7: SLB25102401
A8: 예시(SL-700, White, 2025-10-24) | B8: SLW25102401
A9: 예시(SL-550, Blue, 2025-10-24) | B9: SLU25102401

Sheet Binder_Visc
A1: 바인더명 | B1: 점도하한 | C1: 점도상한 | D1: UV상한
A2: PBHAv1.0 | B2: 360 | C2: 460 | D2: 0.4
A3: PBHBv1.0 | B3: 240 | C3: 400 | D3: 0.1
A4: SBCT | B4: 170 | C4: 220
A5: SCRA | B5: 50 | C5: 70

Sheet README
A1: 항목 | B1: 내용
A2: 파일 목적 | B2: 액상 잉크 Lot 추적 및 Spec 기준/측정 기록 관리 (Binder→단일색 잉크 중심)
A3: HEMA 바인더 매핑 | B3: PL- 계열 → PBHAv1.0, NPL- 계열 → PBHBv1.0
A4: HEMA 단일색 Lot 규칙 | B4: Lot규칙_단일색 시트 참조. 단일색_수입검사에 'Lot(제안)' 자동 생성 열 제공.
A5: Binder Spec | B5: PBHAv1.0 UV≤0.40, 점도 410±50; SBCT 170~220; SCRA 50~70 (25°C)
A6: Silicone 잉크 구분 | B6: Silicone Ink 1=SBCT 기반, Silicone Ink 3=SCRA 기반. Spec_Single_Silicone의 BinderType 컬럼에서 설정.
A7: 자동화 포인트 | B7: 단일색_수입검사: 제품코드→점도 하한/상한 자동 조회·판정. 단일색_착색력: ΔE 계산. 바인더_제조_입고: Lot 자동.
A9: 수정 이력
A10: Binder_Visc 시트에 UV상한 컬럼 추가. 바인더_제조_입고 F열 판정 수식 완전 재작성 (단순화).

Sheet 바인더_제조_입고
A1: 제조/입고일 | B1: 바인더명 | C1: Lot(자동) | D1: 점도(cP) | E1: UV흡광도(선택) | F1: 판정 | G1: 비고
A2: 45880 | B2: PBHAv1.0 | C2: =IF(B2="PBHAv1.0","PCB"&TEXT(A2,"yyyymmdd")&"-01",IF(B2="SBCT","SBCT"&TEXT(A2,"yyyymmdd"),IF(B2="SCRA","SCRA"&TEXT(A2,"yyyymmdd"),""))) -> PCB20250811-01 | D2: =(423.6+415.8+415.8)/3 -> 418.4 | E2: 0.028093 | F2: =IF(ISBLANK(B2),"",IF(B2="PBHAv1.0",IF(OR(ISBLANK(D2),ISBLANK(E2)),"",IF(AND(D2>=360,D2<=460,E2<=0.4),"적합","부적합")),IF(ISBLANK(B2),"",IF(B2="PBHBv1.0",IF(OR(ISBLANK(D2),ISBLANK(E2)),"",IF(AND(D2>=240,D2<=400,E2<=0.1),"적합","부적합")),IF(ISBLANK(D2),"",IF(B2="SBCT",IF(AND(D2>=170,D2<=220),"적합","부적합"),IF(B2="SCRA",IF(AND(D2>=50,D2<=70),"적합","부적합"),""))))))) -> 적합
A3: 45887 | B3: PBHBv1.0 | C3: =IF(B3="PBHAv1.0","PCB"&TEXT(A3,"yyyymmdd")&"-01",IF(B3="PBHBv1.0","NPCB"&TEXT(A3,"yyyymmdd")&"-01",IF(B3="SBCT","SBCT"&TEXT(A3,"yyyymmdd"),IF(B3="SCRA","SCRA"&TEXT(A3,"yyyymmdd"),"")))) -> NPCB20250818-01 | D3: =(261.6+265.2+265.8)/3 -> 264.2 | E3: 0.003852 | F3: =IF(ISBLANK(B3),"",IF(B3="PBHAv1.0",IF(OR(ISBLANK(D3),ISBLANK(E3)),"",IF(AND(D3>=360,D3<=460,E3<=0.4),"적합","부적합")),IF(ISBLANK(B3),"",IF(B3="PBHBv1.0",IF(OR(ISBLANK(D3),ISBLANK(E3)),"",IF(AND(D3>=240,D3<=400,E3<=0.1),"적합","부적합")),IF(ISBLANK(D3),"",IF(B3="SBCT",IF(AND(D3>=170,D3<=220),"적합","부적합"),IF(B3="SCRA",IF(AND(D3>=50,D3<=70),"적합","부적합"),""))))))) -> 적합
A4: 45887 | B4: PBHAv1.0 | C4: =IF(B4="PBHAv1.0","PCB"&TEXT(A4,"yyyymmdd")&"-01",IF(B4="PBHBv1.0","BIH"&TEXT(A4,"yyyymmdd")&"-01",IF(B4="SBCT","SBCT"&TEXT(A4,"yyyymmdd"),IF(B4="SCRA","SCRA"&TEXT(A4,"yyyymmdd"),"")))) -> PCB20250818-01 | D4: 410.4 | E4: 0.018726 | F4: =IF(ISBLANK(B4),"",IF(B4="PBHAv1.0",IF(OR(ISBLANK(D4),ISBLANK(E4)),"",IF(AND(D4>=360,D4<=460,E4<=0.4),"적합","부적합")),IF(ISBLANK(B4),"",IF(B4="PBHBv1.0",IF(OR(ISBLANK(D4),ISBLANK(E4)),"",IF(AND(D4>=240,D4<=400,E4<=0.1),"적합","부적합")),IF(ISBLANK(D4),"",IF(B4="SBCT",IF(AND(D4>=170,D4<=220),"적합","부적합"),IF(B4="SCRA",IF(AND(D4>=50,D4<=70),"적합","부적합"),""))))))) -> 적합
A5: 45894 | B5: PBHAv1.0 | C5: =IF(B5="PBHAv1.0","PCB"&TEXT(A5,"yyyymmdd")&"-01",IF(B5="PBHBv1.0","BIH"&TEXT(A5,"yyyymmdd")&"-01",IF(B5="SBCT","SBCT"&TEXT(A5,"yyyymmdd"),IF(B5="SCRA","SCRA"&TEXT(A5,"yyyymmdd"),"")))) -> PCB20250825-01 | D5: =(433.8+432.6+432)/3 -> 432.8 | E5: 0.021492 | F5: =IF(ISBLANK(B5),"",IF(B5="PBHAv1.0",IF(OR(ISBLANK(D5),ISBLANK(E5)),"",IF(AND(D5>=360,D5<=460,E5<=0.4),"적합","부적합")),IF(ISBLANK(B5),"",IF(B5="PBHBv1.0",IF(OR(ISBLANK(D5),ISBLANK(E5)),"",IF(AND(D5>=240,D5<=400,E5<=0.1),"적합","부적합")),IF(ISBLANK(D5),"",IF(B5="SBCT",IF(AND(D5>=170,D5<=220),"적합","부적합"),IF(B5="SCRA",IF(AND(D5>=50,D5<=70),"적합","부적합"),""))))))) -> 적합
A6: 45894 | B6: PBHAv1.0 | C6: =IF(B6="PBHAv1.0","PCB"&TEXT(A6,"yyyymmdd")&"-01",IF(B6="PBHBv1.0","BIH"&TEXT(A6,"yyyymmdd")&"-01",IF(B6="SBCT","SBCT"&TEXT(A6,"yyyymmdd"),IF(B6="SCRA","SCRA"&TEXT(A6,"yyyymmdd"),"")))) -> PCB20250825-01 | D6: =(434.4+433.2+433.2)/3 -> 433.6 | E6: 0.018332 | F6: =IF(ISBLANK(B6),"",IF(B6="PBHAv1.0",IF(OR(ISBLANK(D6),ISBLANK(E6)),"",IF(AND(D6>=360,D6<=460,E6<=0.4),"적합","부적합")),IF(ISBLANK(B6),"",IF(B6="PBHBv1.0",IF(OR(ISBLANK(D6),ISBLANK(E6)),"",IF(AND(D6>=240,D6<=400,E6<=0.1),"적합","부적합")),IF(ISBLANK(D6),"",IF(B6="SBCT",IF(AND(D6>=170,D6<=220),"적합","부적합"),IF(B6="SCRA",IF(AND(D6>=50,D6<=70),"적합","부적합"),""))))))) -> 적합
A7: 45897 | B7: PBHAv1.0 | C7: =IF(B7="PBHAv1.0","PCB"&TEXT(A7,"yyyymmdd")&"-01",IF(B7="PBHBv1.0","BIH"&TEXT(A7,"yyyymmdd")&"-01",IF(B7="SBCT","SBCT"&TEXT(A7,"yyyymmdd"),IF(B7="SCRA","SCRA"&TEXT(A7,"yyyymmdd"),"")))) -> PCB20250828-01 | D7: 385.8 | E7: 0.015824 | F7: =IF(ISBLANK(B7),"",IF(B7="PBHAv1.0",IF(OR(ISBLANK(D7),ISBLANK(E7)),"",IF(AND(D7>=360,D7<=460,E7<=0.4),"적합","부적합")),IF(ISBLANK(B7),"",IF(B7="PBHBv1.0",IF(OR(ISBLANK(D7),ISBLANK(E7)),"",IF(AND(D7>=240,D7<=400,E7<=0.1),"적합","부적합")),IF(ISBLANK(D7),"",IF(B7="SBCT",IF(AND(D7>=170,D7<=220),"적합","부적합"),IF(B7="SCRA",IF(AND(D7>=50,D7<=70),"적합","부적합"),""))))))) -> 적합
A8: 45897 | B8: PBHAv1.0 | C8: =IF(B8="PBHAv1.0","PCB"&TEXT(A8,"yyyymmdd")&"-01",IF(B8="PBHBv1.0","BIH"&TEXT(A8,"yyyymmdd")&"-01",IF(B8="SBCT","SBCT"&TEXT(A8,"yyyymmdd"),IF(B8="SCRA","SCRA"&TEXT(A8,"yyyymmdd"),"")))) -> PCB20250828-01 | D8: 390 | E8: 0.017604 | F8: =IF(ISBLANK(B8),"",IF(B8="PBHAv1.0",IF(OR(ISBLANK(D8),ISBLANK(E8)),"",IF(AND(D8>=360,D8<=460,E8<=0.4),"적합","부적합")),IF(ISBLANK(B8),"",IF(B8="PBHBv1.0",IF(OR(ISBLANK(D8),ISBLANK(E8)),"",IF(AND(D8>=240,D8<=400,E8<=0.1),"적합","부적합")),IF(ISBLANK(D8),"",IF(B8="SBCT",IF(AND(D8>=170,D8<=220),"적합","부적합"),IF(B8="SCRA",IF(AND(D8>=50,D8<=70),"적합","부적합"),""))))))) -> 적합
A9: 45898 | B9: PBHAv1.0 | C9: =IF(B9="PBHAv1.0","PCB"&TEXT(A9,"yyyymmdd")&"-01",IF(B9="PBHBv1.0","BIH"&TEXT(A9,"yyyymmdd")&"-01",IF(B9="SBCT","SBCT"&TEXT(A9,"yyyymmdd"),IF(B9="SCRA","SCRA"&TEXT(A9,"yyyymmdd"),"")))) -> PCB20250829-01 | D9: 409.2 | E9: 0.0159 | F9: =IF(ISBLANK(B9),"",IF(B9="PBHAv1.0",IF(OR(ISBLANK(D9),ISBLANK(E9)),"",IF(AND(D9>=360,D9<=460,E9<=0.4),"적합","부적합")),IF(ISBLANK(B9),"",IF(B9="PBHBv1.0",IF(OR(ISBLANK(D9),ISBLANK(E9)),"",IF(AND(D9>=240,D9<=400,E9<=0.1),"적합","부적합")),IF(ISBLANK(D9),"",IF(B9="SBCT",IF(AND(D9>=170,D9<=220),"적합","부적합"),IF(B9="SCRA",IF(AND(D9>=50,D9<=70),"적합","부적합"),""))))))) -> 적합
A10: 45901 | B10: PBHBv1.0 | C10: =IF(B10="PBHAv1.0","PCB"&TEXT(A10,"yyyymmdd")&"-01",IF(B10="PBHBv1.0","NPCB"&TEXT(A10,"yyyymmdd")&"-01",IF(B10="SBCT","SBCT"&TEXT(A10,"yyyymmdd"),IF(B10="SCRA","SCRA"&TEXT(A10,"yyyymmdd"),"")))) -> NPCB20250901-01 | D10: =(260.4+262.2+262.8)/3 -> 261.8 | E10: 0.006518 | F10: =IF(ISBLANK(B10),"",IF(B10="PBHAv1.0",IF(OR(ISBLANK(D10),ISBLANK(E10)),"",IF(AND(D10>=360,D10<=460,E10<=0.4),"적합","부적합")),IF(ISBLANK(B10),"",IF(B10="PBHBv1.0",IF(OR(ISBLANK(D10),ISBLANK(E10)),"",IF(AND(D10>=240,D10<=400,E10<=0.1),"적합","부적합")),IF(ISBLANK(D10),"",IF(B10="SBCT",IF(AND(D10>=170,D10<=220),"적합","부적합"),IF(B10="SCRA",IF(AND(D10>=50,D10<=70),"적합","부적합"),""))))))) -> 적합
A11: 45901 | B11: PBHBv1.0 | C11: =IF(B11="PBHAv1.0","PCB"&TEXT(A11,"yyyymmdd")&"-01",IF(B11="PBHBv1.0","NPCB"&TEXT(A11,"yyyymmdd")&"-01",IF(B11="SBCT","SBCT"&TEXT(A11,"yyyymmdd"),IF(B11="SCRA","SCRA"&TEXT(A11,"yyyymmdd"),"")))) -> NPCB20250901-01 | D11: =(261+263.4+264)/3 -> 262.8 | E11: 0.006525 | F11: =IF(ISBLANK(B11),"",IF(B11="PBHAv1.0",IF(OR(ISBLANK(D11),ISBLANK(E11)),"",IF(AND(D11>=360,D11<=460,E11<=0.4),"적합","부적합")),IF(ISBLANK(B11),"",IF(B11="PBHBv1.0",IF(OR(ISBLANK(D11),ISBLANK(E11)),"",IF(AND(D11>=240,D11<=400,E11<=0.1),"적합","부적합")),IF(ISBLANK(D11),"",IF(B11="SBCT",IF(AND(D11>=170,D11<=220),"적합","부적합"),IF(B11="SCRA",IF(AND(D11>=50,D11<=70),"적합","부적합"),""))))))) -> 적합
A12: 45902 | B12: PBHAv1.0 | C12: =IF(B12="PBHAv1.0","PCB"&TEXT(A12,"yyyymmdd")&"-01",IF(B12="SBCT","SBCT"&TEXT(A12,"yyyymmdd"),IF(B12="SCRA","SCRA"&TEXT(A12,"yyyymmdd"),""))) -> PCB20250902-01 | D12: =(388.2+389.4+397.8)/3 -> 391.8 | E12: 0.010118 | F12: =IF(ISBLANK(B12),"",IF(B12="PBHAv1.0",IF(OR(ISBLANK(D12),ISBLANK(E12)),"",IF(AND(D12>=360,D12<=460,E12<=0.4),"적합","부적합")),IF(ISBLANK(D12),"",IF(B12="SBCT",IF(AND(D12>=170,D12<=220),"적합","부적합"),IF(B12="SCRA",IF(AND(D12>=50,D12<=70),"적합","부적합"),""))))) -> 적합
A13: 45902 | B13: PBHAv1.0 | C13: =IF(B13="PBHAv1.0","PCB"&TEXT(A13,"yyyymmdd")&"-01",IF(B13="SBCT","SBCT"&TEXT(A13,"yyyymmdd"),IF(B13="SCRA","SCRA"&TEXT(A13,"yyyymmdd"),""))) -> PCB20250902-01 | D13: =(366+369.6+372)/3 -> 369.2 | E13: 0.01474 | F13: =IF(ISBLANK(B13),"",IF(B13="PBHAv1.0",IF(OR(ISBLANK(D13),ISBLANK(E13)),"",IF(AND(D13>=360,D13<=460,E13<=0.4),"적합","부적합")),IF(ISBLANK(D13),"",IF(B13="SBCT",IF(AND(D13>=170,D13<=220),"적합","부적합"),IF(B13="SCRA",IF(AND(D13>=50,D13<=70),"적합","부적합"),""))))) -> 적합
A14: 45904 | B14: PBHAv1.0 | C14: =IF(B14="PBHAv1.0","PCB"&TEXT(A14,"yyyymmdd")&"-01",IF(B14="SBCT","SBCT"&TEXT(A14,"yyyymmdd"),IF(B14="SCRA","SCRA"&TEXT(A14,"yyyymmdd"),""))) -> PCB20250904-01 | D14: =(375+381.6+380.5)/3 -> 379.03333 | E14: 0.008633 | F14: =IF(ISBLANK(B14),"",IF(B14="PBHAv1.0",IF(OR(ISBLANK(D14),ISBLANK(E14)),"",IF(AND(D14>=360,D14<=460,E14<=0.4),"적합","부적합")),IF(ISBLANK(D14),"",IF(B14="SBCT",IF(AND(D14>=170,D14<=220),"적합","부적합"),IF(B14="SCRA",IF(AND(D14>=50,D14<=70),"적합","부적합"),""))))) -> 적합
A15: 45904 | B15: PBHAv1.0 | C15: =IF(B15="PBHAv1.0","PCB"&TEXT(A15,"yyyymmdd")&"-01",IF(B15="SBCT","SBCT"&TEXT(A15,"yyyymmdd"),IF(B15="SCRA","SCRA"&TEXT(A15,"yyyymmdd"),""))) -> PCB20250904-01 | D15: =(372.6+375.6+376.2)/3 -> 374.8 | E15: 0.009911 | F15: =IF(ISBLANK(B15),"",IF(B15="PBHAv1.0",IF(OR(ISBLANK(D15),ISBLANK(E15)),"",IF(AND(D15>=360,D15<=460,E15<=0.4),"적합","부적합")),IF(ISBLANK(D15),"",IF(B15="SBCT",IF(AND(D15>=170,D15<=220),"적합","부적합"),IF(B15="SCRA",IF(AND(D15>=50,D15<=70),"적합","부적합"),""))))) -> 적합
A16: 45905 | B16: PBHBv1.0 | C16: =IF(B16="PBHAv1.0","PCB"&TEXT(A16,"yyyymmdd")&"-01",IF(B16="PBHBv1.0","BIH"&TEXT(A16,"yyyymmdd")&"-01",IF(B16="SBCT","SBCT"&TEXT(A16,"yyyymmdd"),IF(B16="SCRA","SCRA"&TEXT(A16,"yyyymmdd"),"")))) -> BIH20250905-01 | D16: 275.4 | E16: 0.002101 | F16: =IF(ISBLANK(B16),"",IF(B16="PBHAv1.0",IF(OR(ISBLANK(D16),ISBLANK(E16)),"",IF(AND(D16>=360,D16<=460,E16<=0.4),"적합","부적합")),IF(ISBLANK(B16),"",IF(B16="PBHBv1.0",IF(OR(ISBLANK(D16),ISBLANK(E16)),"",IF(AND(D16>=240,D16<=400,E16<=0.1),"적합","부적합")),IF(ISBLANK(D16),"",IF(B16="SBCT",IF(AND(D16>=170,D16<=220),"적합","부적합"),IF(B16="SCRA",IF(AND(D16>=50,D16<=70),"적합","부적합"),""))))))) -> 적합
A17: 45905 | B17: PBHBv1.0 | C17: =IF(B17="PBHAv1.0","PCB"&TEXT(A17,"yyyymmdd")&"-01",IF(B17="PBHBv1.0","BIH"&TEXT(A17,"yyyymmdd")&"-01",IF(B17="SBCT","SBCT"&TEXT(A17,"yyyymmdd"),IF(B17="SCRA","SCRA"&TEXT(A17,"yyyymmdd"),"")))) -> BIH20250905-01 | D17: 287.4 | E17: 0.000933 | F17: =IF(ISBLANK(B17),"",IF(B17="PBHAv1.0",IF(OR(ISBLANK(D17),ISBLANK(E17)),"",IF(AND(D17>=360,D17<=460,E17<=0.4),"적합","부적합")),IF(ISBLANK(B17),"",IF(B17="PBHBv1.0",IF(OR(ISBLANK(D17),ISBLANK(E17)),"",IF(AND(D17>=240,D17<=400,E17<=0.1),"적합","부적합")),IF(ISBLANK(D17),"",IF(B17="SBCT",IF(AND(D17>=170,D17<=220),"적합","부적합"),IF(B17="SCRA",IF(AND(D17>=50,D17<=70),"적합","부적합"),""))))))) -> 적합
A18: 45908 | B18: PBHAv1.0 | C18: =IF(B18="PBHAv1.0","PCB"&TEXT(A18,"yyyymmdd")&"-01",IF(B18="PBHBv1.0","BIH"&TEXT(A18,"yyyymmdd")&"-01",IF(B18="SBCT","SBCT"&TEXT(A18,"yyyymmdd"),IF(B18="SCRA","SCRA"&TEXT(A18,"yyyymmdd"),"")))) -> PCB20250908-01 | D18: 414.6 | E18: 0.009494 | F18: =IF(ISBLANK(B18),"",IF(B18="PBHAv1.0",IF(OR(ISBLANK(D18),ISBLANK(E18)),"",IF(AND(D18>=360,D18<=460,E18<=0.4),"적합","부적합")),IF(ISBLANK(B18),"",IF(B18="PBHBv1.0",IF(OR(ISBLANK(D18),ISBLANK(E18)),"",IF(AND(D18>=240,D18<=400,E18<=0.1),"적합","부적합")),IF(ISBLANK(D18),"",IF(B18="SBCT",IF(AND(D18>=170,D18<=220),"적합","부적합"),IF(B18="SCRA",IF(AND(D18>=50,D18<=70),"적합","부적합"),""))))))) -> 적합
A19: 45908 | B19: PBHAv1.0 | C19: =IF(B19="PBHAv1.0","PCB"&TEXT(A19,"yyyymmdd")&"-01",IF(B19="PBHBv1.0","BIH"&TEXT(A19,"yyyymmdd")&"-01",IF(B19="SBCT","SBCT"&TEXT(A19,"yyyymmdd"),IF(B19="SCRA","SCRA"&TEXT(A19,"yyyymmdd"),"")))) -> PCB20250908-01 | D19: 385.2 | E19: 0.010691 | F19: =IF(ISBLANK(B19),"",IF(B19="PBHAv1.0",IF(OR(ISBLANK(D19),ISBLANK(E19)),"",IF(AND(D19>=360,D19<=460,E19<=0.4),"적합","부적합")),IF(ISBLANK(B19),"",IF(B19="PBHBv1.0",IF(OR(ISBLANK(D19),ISBLANK(E19)),"",IF(AND(D19>=240,D19<=400,E19<=0.1),"적합","부적합")),IF(ISBLANK(D19),"",IF(B19="SBCT",IF(AND(D19>=170,D19<=220),"적합","부적합"),IF(B19="SCRA",IF(AND(D19>=50,D19<=70),"적합","부적합"),""))))))) -> 적합
A20: 45909 | B20: PBHAv1.0 | C20: =IF(B20="PBHAv1.0","PCB"&TEXT(A20,"yyyymmdd")&"-01",IF(B20="PBHBv1.0","BIH"&TEXT(A20,"yyyymmdd")&"-01",IF(B20="SBCT","SBCT"&TEXT(A20,"yyyymmdd"),IF(B20="SCRA","SCRA"&TEXT(A20,"yyyymmdd"),"")))) -> PCB20250909-01 | D20: =(382.8+369.6+368.4)/3 -> 373.6 | E20: 0.008874 | F20: =IF(ISBLANK(B20),"",IF(B20="PBHAv1.0",IF(OR(ISBLANK(D20),ISBLANK(E20)),"",IF(AND(D20>=360,D20<=460,E20<=0.4),"적합","부적합")),IF(ISBLANK(B20),"",IF(B20="PBHBv1.0",IF(OR(ISBLANK(D20),ISBLANK(E20)),"",IF(AND(D20>=240,D20<=400,E20<=0.1),"적합","부적합")),IF(ISBLANK(D20),"",IF(B20="SBCT",IF(AND(D20>=170,D20<=220),"적합","부적합"),IF(B20="SCRA",IF(AND(D20>=50,D20<=70),"적합","부적합"),""))))))) -> 적합
A21: 45909 | B21: PBHAv1.0 | C21: =IF(B21="PBHAv1.0","PCB"&TEXT(A21,"yyyymmdd")&"-01",IF(B21="PBHBv1.0","BIH"&TEXT(A21,"yyyymmdd")&"-01",IF(B21="SBCT","SBCT"&TEXT(A21,"yyyymmdd"),IF(B21="SCRA","SCRA"&TEXT(A21,"yyyymmdd"),"")))) -> PCB20250909-01 | D21: =(365.4+367.8+370.2)/3 -> 367.8 | E21: 0.00756 | F21: =IF(ISBLANK(B21),"",IF(B21="PBHAv1.0",IF(OR(ISBLANK(D21),ISBLANK(E21)),"",IF(AND(D21>=360,D21<=460,E21<=0.4),"적합","부적합")),IF(ISBLANK(B21),"",IF(B21="PBHBv1.0",IF(OR(ISBLANK(D21),ISBLANK(E21)),"",IF(AND(D21>=240,D21<=400,E21<=0.1),"적합","부적합")),IF(ISBLANK(D21),"",IF(B21="SBCT",IF(AND(D21>=170,D21<=220),"적합","부적합"),IF(B21="SCRA",IF(AND(D21>=50,D21<=70),"적합","부적합"),""))))))) -> 적합
A22: 45911 | B22: PBHAv1.0 | C22: =IF(B22="PBHAv1.0","PCB"&TEXT(A22,"yyyymmdd")&"-01",IF(B22="PBHBv1.0","BIH"&TEXT(A22,"yyyymmdd")&"-01",IF(B22="SBCT","SBCT"&TEXT(A22,"yyyymmdd"),IF(B22="SCRA","SCRA"&TEXT(A22,"yyyymmdd"),"")))) -> PCB20250911-01 | D22: =(391.2+391.8+391.7)/3 -> 391.56667 | E22: 0.008242 | F22: =IF(ISBLANK(B22),"",IF(B22="PBHAv1.0",IF(OR(ISBLANK(D22),ISBLANK(E22)),"",IF(AND(D22>=360,D22<=460,E22<=0.4),"적합","부적합")),IF(ISBLANK(B22),"",IF(B22="PBHBv1.0",IF(OR(ISBLANK(D22),ISBLANK(E22)),"",IF(AND(D22>=240,D22<=400,E22<=0.1),"적합","부적합")),IF(ISBLANK(D22),"",IF(B22="SBCT",IF(AND(D22>=170,D22<=220),"적합","부적합"),IF(B22="SCRA",IF(AND(D22>=50,D22<=70),"적합","부적합"),""))))))) -> 적합
A23: 45911 | B23: PBHAv1.0 | C23: =IF(B23="PBHAv1.0","PCB"&TEXT(A23,"yyyymmdd")&"-01",IF(B23="PBHBv1.0","BIH"&TEXT(A23,"yyyymmdd")&"-01",IF(B23="SBCT","SBCT"&TEXT(A23,"yyyymmdd"),IF(B23="SCRA","SCRA"&TEXT(A23,"yyyymmdd"),"")))) -> PCB20250911-01 | D23: =(361.2+362.4+364.2)/3 -> 362.6 | E23: 0.011026 | F23: =IF(ISBLANK(B23),"",IF(B23="PBHAv1.0",IF(OR(ISBLANK(D23),ISBLANK(E23)),"",IF(AND(D23>=360,D23<=460,E23<=0.4),"적합","부적합")),IF(ISBLANK(B23),"",IF(B23="PBHBv1.0",IF(OR(ISBLANK(D23),ISBLANK(E23)),"",IF(AND(D23>=240,D23<=400,E23<=0.1),"적합","부적합")),IF(ISBLANK(D23),"",IF(B23="SBCT",IF(AND(D23>=170,D23<=220),"적합","부적합"),IF(B23="SCRA",IF(AND(D23>=50,D23<=70),"적합","부적합"),""))))))) -> 적합
A24: 45910 | B24: PBHBv1.0 | C24: =IF(B24="PBHAv1.0","PCB"&TEXT(A24,"yyyymmdd")&"-01",IF(B24="PBHBv1.0","BIH"&TEXT(A24,"yyyymmdd")&"-01",IF(B24="SBCT","SBCT"&TEXT(A24,"yyyymmdd"),IF(B24="SCRA","SCRA"&TEXT(A24,"yyyymmdd"),"")))) -> BIH20250910-01 | D24: =(269.4+270.6+271.8)/3 -> 270.6 | E24: 0.004882 | F24: =IF(ISBLANK(B24),"",IF(B24="PBHAv1.0",IF(OR(ISBLANK(D24),ISBLANK(E24)),"",IF(AND(D24>=360,D24<=460,E24<=0.4),"적합","부적합")),IF(ISBLANK(B24),"",IF(B24="PBHBv1.0",IF(OR(ISBLANK(D24),ISBLANK(E24)),"",IF(AND(D24>=240,D24<=400,E24<=0.1),"적합","부적합")),IF(ISBLANK(D24),"",IF(B24="SBCT",IF(AND(D24>=170,D24<=220),"적합","부적합"),IF(B24="SCRA",IF(AND(D24>=50,D24<=70),"적합","부적합"),""))))))) -> 적합
A25: 45910 | B25: PBHBv1.0 | C25: =IF(B25="PBHAv1.0","PCB"&TEXT(A25,"yyyymmdd")&"-01",IF(B25="PBHBv1.0","BIH"&TEXT(A25,"yyyymmdd")&"-01",IF(B25="SBCT","SBCT"&TEXT(A25,"yyyymmdd"),IF(B25="SCRA","SCRA"&TEXT(A25,"yyyymmdd"),"")))) -> BIH20250910-01 | D25: =(280.2+282.6+283.8)/3 -> 282.2 | E25: 0.004006 | F25: =IF(ISBLANK(B25),"",IF(B25="PBHAv1.0",IF(OR(ISBLANK(D25),ISBLANK(E25)),"",IF(AND(D25>=360,D25<=460,E25<=0.4),"적합","부적합")),IF(ISBLANK(B25),"",IF(B25="PBHBv1.0",IF(OR(ISBLANK(D25),ISBLANK(E25)),"",IF(AND(D25>=240,D25<=400,E25<=0.1),"적합","부적합")),IF(ISBLANK(D25),"",IF(B25="SBCT",IF(AND(D25>=170,D25<=220),"적합","부적합"),IF(B25="SCRA",IF(AND(D25>=50,D25<=70),"적합","부적합"),""))))))) -> 적합
A26: 45912 | B26: PBHBv1.0 | C26: =IF(B26="PBHAv1.0","PCB"&TEXT(A26,"yyyymmdd")&"-01",IF(B26="PBHBv1.0","BIH"&TEXT(A26,"yyyymmdd")&"-01",IF(B26="SBCT","SBCT"&TEXT(A26,"yyyymmdd"),IF(B26="SCRA","SCRA"&TEXT(A26,"yyyymmdd"),"")))) -> BIH20250912-01 | D26: =(262.2+264+265.2)/3 -> 263.8 | E26: 0.004019 | F26: =IF(ISBLANK(B26),"",IF(B26="PBHAv1.0",IF(OR(ISBLANK(D26),ISBLANK(E26)),"",IF(AND(D26>=360,D26<=460,E26<=0.4),"적합","부적합")),IF(ISBLANK(B26),"",IF(B26="PBHBv1.0",IF(OR(ISBLANK(D26),ISBLANK(E26)),"",IF(AND(D26>=240,D26<=400,E26<=0.1),"적합","부적합")),IF(ISBLANK(D26),"",IF(B26="SBCT",IF(AND(D26>=170,D26<=220),"적합","부적합"),IF(B26="SCRA",IF(AND(D26>=50,D26<=70),"적합","부적합"),""))))))) -> 적합
A27: 45912 | B27: PBHBv1.0 | C27: =IF(B27="PBHAv1.0","PCB"&TEXT(A27,"yyyymmdd")&"-01",IF(B27="PBHBv1.0","BIH"&TEXT(A27,"yyyymmdd")&"-01",IF(B27="SBCT","SBCT"&TEXT(A27,"yyyymmdd"),IF(B27="SCRA","SCRA"&TEXT(A27,"yyyymmdd"),"")))) -> BIH20250912-01 | D27: =(267.6+270.6+271.8)/3 -> 270 | E27: 0.005236 | F27: =IF(ISBLANK(B27),"",IF(B27="PBHAv1.0",IF(OR(ISBLANK(D27),ISBLANK(E27)),"",IF(AND(D27>=360,D27<=460,E27<=0.4),"적합","부적합")),IF(ISBLANK(B27),"",IF(B27="PBHBv1.0",IF(OR(ISBLANK(D27),ISBLANK(E27)),"",IF(AND(D27>=240,D27<=400,E27<=0.1),"적합","부적합")),IF(ISBLANK(D27),"",IF(B27="SBCT",IF(AND(D27>=170,D27<=220),"적합","부적합"),IF(B27="SCRA",IF(AND(D27>=50,D27<=70),"적합","부적합"),""))))))) -> 적합
A28: 45930 | B28: PBHAv1.0 | C28: =IF(B28="PBHAv1.0","PCB"&TEXT(A28,"yyyymmdd")&"-01",IF(B28="PBHBv1.0","BIH"&TEXT(A28,"yyyymmdd")&"-01",IF(B28="SBCT","SBCT"&TEXT(A28,"yyyymmdd"),IF(B28="SCRA","SCRA"&TEXT(A28,"yyyymmdd"),"")))) -> PCB20250930-01 | D28: 400.2 | E28: 0.012581 | F28: =IF(ISBLANK(B28),"",IF(B28="PBHAv1.0",IF(OR(ISBLANK(D28),ISBLANK(E28)),"",IF(AND(D28>=360,D28<=460,E28<=0.4),"적합","부적합")),IF(ISBLANK(B28),"",IF(B28="PBHBv1.0",IF(OR(ISBLANK(D28),ISBLANK(E28)),"",IF(AND(D28>=240,D28<=400,E28<=0.1),"적합","부적합")),IF(ISBLANK(D28),"",IF(B28="SBCT",IF(AND(D28>=170,D28<=220),"적합","부적합"),IF(B28="SCRA",IF(AND(D28>=50,D28<=70),"적합","부적합"),""))))))) -> 적합
A29: 45930 | B29: PBHAv1.0 | C29: =IF(B29="PBHAv1.0","PCB"&TEXT(A29,"yyyymmdd")&"-01",IF(B29="PBHBv1.0","BIH"&TEXT(A29,"yyyymmdd")&"-01",IF(B29="SBCT","SBCT"&TEXT(A29,"yyyymmdd"),IF(B29="SCRA","SCRA"&TEXT(A29,"yyyymmdd"),"")))) -> PCB20250930-01 | D29: 371.4 | E29: 0.011931 | F29: =IF(ISBLANK(B29),"",IF(B29="PBHAv1.0",IF(OR(ISBLANK(D29),ISBLANK(E29)),"",IF(AND(D29>=360,D29<=460,E29<=0.4),"적합","부적합")),IF(ISBLANK(B29),"",IF(B29="PBHBv1.0",IF(OR(ISBLANK(D29),ISBLANK(E29)),"",IF(AND(D29>=240,D29<=400,E29<=0.1),"적합","부적합")),IF(ISBLANK(D29),"",IF(B29="SBCT",IF(AND(D29>=170,D29<=220),"적합","부적합"),IF(B29="SCRA",IF(AND(D29>=50,D29<=70),"적합","부적합"),""))))))) -> 적합
A30: 45945 | B30: PBHAv1.0 | C30: =IF(B30="PBHAv1.0","PCB"&TEXT(A30,"yyyymmdd")&"-01",IF(B30="PBHBv1.0","BIH"&TEXT(A30,"yyyymmdd")&"-01",IF(B30="SBCT","SBCT"&TEXT(A30,"yyyymmdd"),IF(B30="SCRA","SCRA"&TEXT(A30,"yyyymmdd"),"")))) -> PCB20251015-01 | D30: 401.4 | E30: 0.007085 | F30: =IF(ISBLANK(B30),"",IF(B30="PBHAv1.0",IF(OR(ISBLANK(D30),ISBLANK(E30)),"",IF(AND(D30>=360,D30<=460,E30<=0.4),"적합","부적합")),IF(ISBLANK(B30),"",IF(B30="PBHBv1.0",IF(OR(ISBLANK(D30),ISBLANK(E30)),"",IF(AND(D30>=240,D30<=400,E30<=0.1),"적합","부적합")),IF(ISBLANK(D30),"",IF(B30="SBCT",IF(AND(D30>=170,D30<=220),"적합","부적합"),IF(B30="SCRA",IF(AND(D30>=50,D30<=70),"적합","부적합"),""))))))) -> 적합
A31: 45945 | B31: PBHAv1.0 | C31: =IF(B31="PBHAv1.0","PCB"&TEXT(A31,"yyyymmdd")&"-01",IF(B31="PBHBv1.0","BIH"&TEXT(A31,"yyyymmdd")&"-01",IF(B31="SBCT","SBCT"&TEXT(A31,"yyyymmdd"),IF(B31="SCRA","SCRA"&TEXT(A31,"yyyymmdd"),"")))) -> PCB20251015-01 | D31: 389.4 | E31: 0.006187 | F31: =IF(ISBLANK(B31),"",IF(B31="PBHAv1.0",IF(OR(ISBLANK(D31),ISBLANK(E31)),"",IF(AND(D31>=360,D31<=460,E31<=0.4),"적합","부적합")),IF(ISBLANK(B31),"",IF(B31="PBHBv1.0",IF(OR(ISBLANK(D31),ISBLANK(E31)),"",IF(AND(D31>=240,D31<=400,E31<=0.1),"적합","부적합")),IF(ISBLANK(D31),"",IF(B31="SBCT",IF(AND(D31>=170,D31<=220),"적합","부적합"),IF(B31="SCRA",IF(AND(D31>=50,D31<=70),"적합","부적합"),""))))))) -> 적합
A32: 45946 | B32: PBHAv1.0 | C32: =IF(B32="PBHAv1.0","PCB"&TEXT(A32,"yyyymmdd")&"-01",IF(B32="PBHBv1.0","BIH"&TEXT(A32,"yyyymmdd")&"-01",IF(B32="SBCT","SBCT"&TEXT(A32,"yyyymmdd"),IF(B32="SCRA","SCRA"&TEXT(A32,"yyyymmdd"),"")))) -> PCB20251016-01 | D32: 367.2 | E32: 0.007573 | F32: =IF(ISBLANK(B32),"",IF(B32="PBHAv1.0",IF(OR(ISBLANK(D32),ISBLANK(E32)),"",IF(AND(D32>=360,D32<=460,E32<=0.4),"적합","부적합")),IF(ISBLANK(B32),"",IF(B32="PBHBv1.0",IF(OR(ISBLANK(D32),ISBLANK(E32)),"",IF(AND(D32>=240,D32<=400,E32<=0.1),"적합","부적합")),IF(ISBLANK(D32),"",IF(B32="SBCT",IF(AND(D32>=170,D32<=220),"적합","부적합"),IF(B32="SCRA",IF(AND(D32>=50,D32<=70),"적합","부적합"),""))))))) -> 적합
A33: 45946 | B33: PBHAv1.0 | C33: =IF(B33="PBHAv1.0","PCB"&TEXT(A33,"yyyymmdd")&"-01",IF(B33="PBHBv1.0","BIH"&TEXT(A33,"yyyymmdd")&"-01",IF(B33="SBCT","SBCT"&TEXT(A33,"yyyymmdd"),IF(B33="SCRA","SCRA"&TEXT(A33,"yyyymmdd"),"")))) -> PCB20251016-01 | D33: 361.2 | E33: 0.002582 | F33: =IF(ISBLANK(B33),"",IF(B33="PBHAv1.0",IF(OR(ISBLANK(D33),ISBLANK(E33)),"",IF(AND(D33>=360,D33<=460,E33<=0.4),"적합","부적합")),IF(ISBLANK(B33),"",IF(B33="PBHBv1.0",IF(OR(ISBLANK(D33),ISBLANK(E33)),"",IF(AND(D33>=240,D33<=400,E33<=0.1),"적합","부적합")),IF(ISBLANK(D33),"",IF(B33="SBCT",IF(AND(D33>=170,D33<=220),"적합","부적합"),IF(B33="SCRA",IF(AND(D33>=50,D33<=70),"적합","부적합"),""))))))) -> 적합
A34: 45951 | B34: PBHAv1.0 | C34: =IF(B34="PBHAv1.0","PCB"&TEXT(A34,"yyyymmdd")&"-01",IF(B34="PBHBv1.0","BIH"&TEXT(A34,"yyyymmdd")&"-01",IF(B34="SBCT","SBCT"&TEXT(A34,"yyyymmdd"),IF(B34="SCRA","SCRA"&TEXT(A34,"yyyymmdd"),"")))) -> PCB20251021-01 | D34: =(368.4+367.2+367.2)/3 -> 367.6 | E34: 0.024893 | F34: =IF(ISBLANK(B34),"",IF(B34="PBHAv1.0",IF(OR(ISBLANK(D34),ISBLANK(E34)),"",IF(AND(D34>=360,D34<=460,E34<=0.4),"적합","부적합")),IF(ISBLANK(B34),"",IF(B34="PBHBv1.0",IF(OR(ISBLANK(D34),ISBLANK(E34)),"",IF(AND(D34>=240,D34<=400,E34<=0.1),"적합","부적합")),IF(ISBLANK(D34),"",IF(B34="SBCT",IF(AND(D34>=170,D34<=220),"적합","부적합"),IF(B34="SCRA",IF(AND(D34>=50,D34<=70),"적합","부적합"),""))))))) -> 적합
A35: 45951 | B35: PBHAv1.0 | C35: =IF(B35="PBHAv1.0","PCB"&TEXT(A35,"yyyymmdd")&"-01",IF(B35="PBHBv1.0","BIH"&TEXT(A35,"yyyymmdd")&"-01",IF(B35="SBCT","SBCT"&TEXT(A35,"yyyymmdd"),IF(B35="SCRA","SCRA"&TEXT(A35,"yyyymmdd"),"")))) -> PCB20251021-01 | D35: =(350.4+351.6+350.4)/3 -> 350.8 | E35: 0.025525 | F35: =IF(ISBLANK(B35),"",IF(B35="PBHAv1.0",IF(OR(ISBLANK(D35),ISBLANK(E35)),"",IF(AND(D35>=360,D35<=460,E35<=0.4),"적합","부적합")),IF(ISBLANK(B35),"",IF(B35="PBHBv1.0",IF(OR(ISBLANK(D35),ISBLANK(E35)),"",IF(AND(D35>=240,D35<=400,E35<=0.1),"적합","부적합")),IF(ISBLANK(D35),"",IF(B35="SBCT",IF(AND(D35>=170,D35<=220),"적합","부적합"),IF(B35="SCRA",IF(AND(D35>=50,D35<=70),"적합","부적합"),""))))))) -> 부적합
A36: 45953 | B36: PBHAv1.0 | C36: =IF(B36="PBHAv1.0","PCB"&TEXT(A36,"yyyymmdd")&"-01",IF(B36="PBHBv1.0","BIH"&TEXT(A36,"yyyymmdd")&"-01",IF(B36="SBCT","SBCT"&TEXT(A36,"yyyymmdd"),IF(B36="SCRA","SCRA"&TEXT(A36,"yyyymmdd"),"")))) -> PCB20251023-01 | D36: 415.8 | E36: 0.007811 | F36: =IF(ISBLANK(B36),"",IF(B36="PBHAv1.0",IF(OR(ISBLANK(D36),ISBLANK(E36)),"",IF(AND(D36>=360,D36<=460,E36<=0.4),"적합","부적합")),IF(ISBLANK(B36),"",IF(B36="PBHBv1.0",IF(OR(ISBLANK(D36),ISBLANK(E36)),"",IF(AND(D36>=240,D36<=400,E36<=0.1),"적합","부적합")),IF(ISBLANK(D36),"",IF(B36="SBCT",IF(AND(D36>=170,D36<=220),"적합","부적합"),IF(B36="SCRA",IF(AND(D36>=50,D36<=70),"적합","부적합"),""))))))) -> 적합
A37: 45953 | B37: PBHAv1.0 | C37: =IF(B37="PBHAv1.0","PCB"&TEXT(A37,"yyyymmdd")&"-01",IF(B37="PBHBv1.0","BIH"&TEXT(A37,"yyyymmdd")&"-01",IF(B37="SBCT","SBCT"&TEXT(A37,"yyyymmdd"),IF(B37="SCRA","SCRA"&TEXT(A37,"yyyymmdd"),"")))) -> PCB20251023-01 | D37: 388.8 | E37: 0.006953 | F37: =IF(ISBLANK(B37),"",IF(B37="PBHAv1.0",IF(OR(ISBLANK(D37),ISBLANK(E37)),"",IF(AND(D37>=360,D37<=460,E37<=0.4),"적합","부적합")),IF(ISBLANK(B37),"",IF(B37="PBHBv1.0",IF(OR(ISBLANK(D37),ISBLANK(E37)),"",IF(AND(D37>=240,D37<=400,E37<=0.1),"적합","부적합")),IF(ISBLANK(D37),"",IF(B37="SBCT",IF(AND(D37>=170,D37<=220),"적합","부적합"),IF(B37="SCRA",IF(AND(D37>=50,D37<=70),"적합","부적합"),""))))))) -> 적합
A38: 45957 | B38: PBHAv1.0 | C38: =IF(B38="PBHAv1.0","PCB"&TEXT(A38,"yyyymmdd")&"-01",IF(B38="PBHBv1.0","BIH"&TEXT(A38,"yyyymmdd")&"-01",IF(B38="SBCT","SBCT"&TEXT(A38,"yyyymmdd"),IF(B38="SCRA","SCRA"&TEXT(A38,"yyyymmdd"),"")))) -> PCB20251027-01 | D38: 421.73 | E38: 0.013653 | F38: =IF(ISBLANK(B38),"",IF(B38="PBHAv1.0",IF(OR(ISBLANK(D38),ISBLANK(E38)),"",IF(AND(D38>=360,D38<=460,E38<=0.4),"적합","부적합")),IF(ISBLANK(B38),"",IF(B38="PBHBv1.0",IF(OR(ISBLANK(D38),ISBLANK(E38)),"",IF(AND(D38>=240,D38<=400,E38<=0.1),"적합","부적합")),IF(ISBLANK(D38),"",IF(B38="SBCT",IF(AND(D38>=170,D38<=220),"적합","부적합"),IF(B38="SCRA",IF(AND(D38>=50,D38<=70),"적합","부적합"),""))))))) -> 적합
A39: 45957 | B39: PBHAv1.0 | C39: =IF(B39="PBHAv1.0","PCB"&TEXT(A39,"yyyymmdd")&"-01",IF(B39="PBHBv1.0","BIH"&TEXT(A39,"yyyymmdd")&"-01",IF(B39="SBCT","SBCT"&TEXT(A39,"yyyymmdd"),IF(B39="SCRA","SCRA"&TEXT(A39,"yyyymmdd"),"")))) -> PCB20251027-01 | D39: 385.6 | E39: 0.009963 | F39: =IF(ISBLANK(B39),"",IF(B39="PBHAv1.0",IF(OR(ISBLANK(D39),ISBLANK(E39)),"",IF(AND(D39>=360,D39<=460,E39<=0.4),"적합","부적합")),IF(ISBLANK(B39),"",IF(B39="PBHBv1.0",IF(OR(ISBLANK(D39),ISBLANK(E39)),"",IF(AND(D39>=240,D39<=400,E39<=0.1),"적합","부적합")),IF(ISBLANK(D39),"",IF(B39="SBCT",IF(AND(D39>=170,D39<=220),"적합","부적합"),IF(B39="SCRA",IF(AND(D39>=50,D39<=70),"적합","부적합"),""))))))) -> 적합
A40: 45958 | B40: PBHAv1.0 | C40: =IF(B40="PBHAv1.0","PCB"&TEXT(A40,"yyyymmdd")&"-01",IF(B40="PBHBv1.0","BIH"&TEXT(A40,"yyyymmdd")&"-01",IF(B40="SBCT","SBCT"&TEXT(A40,"yyyymmdd"),IF(B40="SCRA","SCRA"&TEXT(A40,"yyyymmdd"),"")))) -> PCB20251028-01 | D40: 381.2 | E40: 0.017637 | F40: =IF(ISBLANK(B40),"",IF(B40="PBHAv1.0",IF(OR(ISBLANK(D40),ISBLANK(E40)),"",IF(AND(D40>=360,D40<=460,E40<=0.4),"적합","부적합")),IF(ISBLANK(B40),"",IF(B40="PBHBv1.0",IF(OR(ISBLANK(D40),ISBLANK(E40)),"",IF(AND(D40>=240,D40<=400,E40<=0.1),"적합","부적합")),IF(ISBLANK(D40),"",IF(B40="SBCT",IF(AND(D40>=170,D40<=220),"적합","부적합"),IF(B40="SCRA",IF(AND(D40>=50,D40<=70),"적합","부적합"),""))))))) -> 적합
...

Sheet 단일색_수입검사
A1: 입고일 | B1: 잉크타입 (HEMA/Silicone) | C1: 색상군 | D1: 제품코드 | E1: 단일색잉크 Lot | F1: 사용된 바인더 Lot | G1: 바인더제조처 (내부/외주) | H1: BinderType(자동) | I1: 점도측정값(cP) | J1: 점도하한 | K1: 점도상한 | L1: 점도판정 | M1: 착색력_L* | N1: 착색력_a* | O1: 착색력_b* | P1: 비고
A2: 45862 | B2: HEMA | C2: Black | D2: PL-850 | E2: =IF(D2="","",IF(B2="Silicone", "SL" & IF(C2="Black","B",IF(C2="White","W",IF(C2="Blue","U",IF(C2="Green","G",IF(C2="Yellow","Y",IF(C2="Red","R",IF(C2="Pink","P",""))))))) & TEXT(A2,"yymmdd") & "01",IF(LEFT(D2,3)="NPL","NPL","PL") & IF(C2="Black","B",IF(C2="White","W",IF(C2="Blue","U",IF(C2="Green","G",IF(C2="Yellow","Y",IF(C2="Red","R",IF(C2="Pink","P",""))))))) & TEXT(A2,"yymmdd") & "01")) -> PLB25072401 | G2: 외주 | H2: =VLOOKUP(D2,'Spec_Single_H&S'!$B$2:$G$42,6,FALSE) -> PBHAv1.0 | J2: =VLOOKUP(D2,'Spec_Single_H&S'!$B$2:$G$42,4,FALSE) -> 60000 | K2: =VLOOKUP(D2,'Spec_Single_H&S'!$B$2:$G$42,5,FALSE) -> 90000 | L2: =IF(AND(NOT(ISBLANK(I2)),I2>=J2,I2<=K2),"적합",IF(ISBLANK(I2),"", "부적합"))
A3: 45883 | B3: HEMA | C3: Blue | D3: PL-580-2(H) | E3: =IF(D3="","",IF(B3="Silicone", "SL" & IF(C3="Black","B",IF(C3="White","W",IF(C3="Blue","U",IF(C3="Green","G",IF(C3="Yellow","Y",IF(C3="Red","R",IF(C3="Pink","P",""))))))) & TEXT(A3,"yymmdd") & "01",IF(LEFT(D3,3)="NPL","NPL","PL") & IF(C3="Black","B",IF(C3="White","W",IF(C3="Blue","U",IF(C3="Green","G",IF(C3="Yellow","Y",IF(C3="Red","R",IF(C3="Pink","P",""))))))) & TEXT(A3,"yymmdd") & "01")) -> PLU25081401 | G3: 외주 | H3: =VLOOKUP(D3,'Spec_Single_H&S'!$B$2:$G$42,6,FALSE) -> PBHAv1.0 | I3: 116900 | J3: =VLOOKUP(D3,'Spec_Single_H&S'!$B$2:$G$42,4,FALSE) -> 53000 | K3: =VLOOKUP(D3,'Spec_Single_H&S'!$B$2:$G$42,5,FALSE) -> 73000 | L3: =IF(AND(NOT(ISBLANK(I3)),I3>=J3,I3<=K3),"적합",IF(ISBLANK(I3),"", "부적합")) -> 부적합 | M3: 11.64 | N3: 6.56 | O3: -23.38
A4: 45883 | B4: HEMA | C4: Blue | D4: NPL-580-2 | E4: =IF(D4="","",IF(B4="Silicone", "SL" & IF(C4="Black","B",IF(C4="White","W",IF(C4="Blue","U",IF(C4="Green","G",IF(C4="Yellow","Y",IF(C4="Red","R",IF(C4="Pink","P",""))))))) & TEXT(A4,"yymmdd") & "01",IF(LEFT(D4,3)="NPL","NPL","PL") & IF(C4="Black","B",IF(C4="White","W",IF(C4="Blue","U",IF(C4="Green","G",IF(C4="Yellow","Y",IF(C4="Red","R",IF(C4="Pink","P",""))))))) & TEXT(A4,"yymmdd") & "01")) -> NPLU25081401 | G4: 외주 | H4: =VLOOKUP(D4,'Spec_Single_H&S'!$B$2:$G$42,6,FALSE) -> PBHBv1.0 | I4: 107600 | J4: =VLOOKUP(D4,'Spec_Single_H&S'!$B$2:$G$42,4,FALSE) -> 53000 | K4: =VLOOKUP(D4,'Spec_Single_H&S'!$B$2:$G$42,5,FALSE) -> 73000 | L4: =IF(AND(NOT(ISBLANK(I4)),I4>=J4,I4<=K4),"적합",IF(ISBLANK(I4),"", "부적합")) -> 부적합 | M4: 10.17 | N4: 6.85 | O4: -23.79
A5: 45889 | B5: HEMA | C5: Blue | D5: PL-550 | E5: =IF(D5="","",IF(B5="Silicone", "SL" & IF(C5="Black","B",IF(C5="White","W",IF(C5="Blue","U",IF(C5="Green","G",IF(C5="Yellow","Y",IF(C5="Red","R",IF(C5="Pink","P",""))))))) & TEXT(A5,"yymmdd") & "01",IF(LEFT(D5,3)="NPL","NPL","PL") & IF(C5="Black","B",IF(C5="White","W",IF(C5="Blue","U",IF(C5="Green","G",IF(C5="Yellow","Y",IF(C5="Red","R",IF(C5="Pink","P",""))))))) & TEXT(A5,"yymmdd") & "01")) -> PLU25082001 | G5: 외주 | H5: =VLOOKUP(D5,'Spec_Single_H&S'!$B$2:$G$42,6,FALSE) -> PBHAv1.0 | I5: 32740 | J5: =VLOOKUP(D5,'Spec_Single_H&S'!$B$2:$G$42,4,FALSE) -> 30000 | K5: =VLOOKUP(D5,'Spec_Single_H&S'!$B$2:$G$42,5,FALSE) -> 40000 | L5: =IF(AND(NOT(ISBLANK(I5)),I5>=J5,I5<=K5),"적합",IF(ISBLANK(I5),"", "부적합")) -> 적합 | M5: 7.91 | N5: 5.95 | O5: -31.82
A6: 45894 | B6: HEMA | C6: Blue | D6: PL-580-2 | E6: =IF(D6="","",IF(B6="Silicone", "SL" & IF(C6="Black","B",IF(C6="White","W",IF(C6="Blue","U",IF(C6="Green","G",IF(C6="Yellow","Y",IF(C6="Red","R",IF(C6="Pink","P",""))))))) & TEXT(A6,"yymmdd") & "01",IF(LEFT(D6,3)="NPL","NPL","PL") & IF(C6="Black","B",IF(C6="White","W",IF(C6="Blue","U",IF(C6="Green","G",IF(C6="Yellow","Y",IF(C6="Red","R",IF(C6="Pink","P",""))))))) & TEXT(A6,"yymmdd") & "01")) -> PLU25082501 | G6: 외주 | H6: =VLOOKUP(D6,'Spec_Single_H&S'!$B$2:$G$42,6,FALSE) -> PBHAv1.0 | I6: 83290 | J6: =VLOOKUP(D6,'Spec_Single_H&S'!$B$2:$G$42,4,FALSE) -> 53000 | K6: =VLOOKUP(D6,'Spec_Single_H&S'!$B$2:$G$42,5,FALSE) -> 73000 | L6: =IF(AND(NOT(ISBLANK(I6)),I6>=J6,I6<=K6),"적합",IF(ISBLANK(I6),"", "부적합")) -> 부적합 | M6: 9.09 | N6: 6.33 | O6: -24.22
A7: 45912 | B7: HEMA | C7: Black | D7: NPL-835-1 | E7: =IF(D7="","",IF(B7="Silicone", "SL" & IF(C7="Black","B",IF(C7="White","W",IF(C7="Blue","U",IF(C7="Green","G",IF(C7="Yellow","Y",IF(C7="Red","R",IF(C7="Pink","P",""))))))) & TEXT(A7,"yymmdd") & "01",IF(LEFT(D7,3)="NPL","NPL","PL") & IF(C7="Black","B",IF(C7="White","W",IF(C7="Blue","U",IF(C7="Green","G",IF(C7="Yellow","Y",IF(C7="Red","R",IF(C7="Pink","P",""))))))) & TEXT(A7,"yymmdd") & "01")) -> NPLB25091201 | G7: 외주 | H7: =VLOOKUP(D7,'Spec_Single_H&S'!$B$2:$G$42,6,FALSE) -> PBHBv1.0 | I7: 109800 | J7: =VLOOKUP(D7,'Spec_Single_H&S'!$B$2:$G$42,4,FALSE) -> 60000 | K7: =VLOOKUP(D7,'Spec_Single_H&S'!$B$2:$G$42,5,FALSE) -> 90000 | L7: =IF(AND(NOT(ISBLANK(I7)),I7>=J7,I7<=K7),"적합",IF(ISBLANK(I7),"", "부적합")) -> 부적합 | M7: 13.17 | N7: 0.21 | O7: 0.31
A8: 45912 | B8: HEMA | C8: Red | D8: NPL-150-2 | E8: =IF(D8="","",IF(B8="Silicone", "SL" & IF(C8="Black","B",IF(C8="White","W",IF(C8="Blue","U",IF(C8="Green","G",IF(C8="Yellow","Y",IF(C8="Red","R",IF(C8="Pink","P",""))))))) & TEXT(A8,"yymmdd") & "01",IF(LEFT(D8,3)="NPL","NPL","PL") & IF(C8="Black","B",IF(C8="White","W",IF(C8="Blue","U",IF(C8="Green","G",IF(C8="Yellow","Y",IF(C8="Red","R",IF(C8="Pink","P",""))))))) & TEXT(A8,"yymmdd") & "01")) -> NPLR25091201 | G8: 외주 | H8: =VLOOKUP(D8,'Spec_Single_H&S'!$B$2:$G$42,6,FALSE) -> PBHBv1.0 | I8: 11570 | J8: =VLOOKUP(D8,'Spec_Single_H&S'!$B$2:$G$42,4,FALSE) -> 6000 | K8: =VLOOKUP(D8,'Spec_Single_H&S'!$B$2:$G$42,5,FALSE) -> 16000 | L8: =IF(AND(NOT(ISBLANK(I8)),I8>=J8,I8<=K8),"적합",IF(ISBLANK(I8),"", "부적합")) -> 적합 | M8: 42.05 | N8: 57.59 | O8: 48.75
A9: 45912 | B9: HEMA | C9: Yellow | D9: NPL-345-2 | E9: =IF(D9="","",IF(B9="Silicone", "SL" & IF(C9="Black","B",IF(C9="White","W",IF(C9="Blue","U",IF(C9="Green","G",IF(C9="Yellow","Y",IF(C9="Red","R",IF(C9="Pink","P",""))))))) & TEXT(A9,"yymmdd") & "01",IF(LEFT(D9,3)="NPL","NPL","PL") & IF(C9="Black","B",IF(C9="White","W",IF(C9="Blue","U",IF(C9="Green","G",IF(C9="Yellow","Y",IF(C9="Red","R",IF(C9="Pink","P",""))))))) & TEXT(A9,"yymmdd") & "01")) -> NPLY25091201 | G9: 외주 | H9: =VLOOKUP(D9,'Spec_Single_H&S'!$B$2:$G$42,6,FALSE) -> PBHBv1.0 | I9: 51510 | J9: =VLOOKUP(D9,'Spec_Single_H&S'!$B$2:$G$42,4,FALSE) -> 20000 | K9: =VLOOKUP(D9,'Spec_Single_H&S'!$B$2:$G$42,5,FALSE) -> 30000 | L9: =IF(AND(NOT(ISBLANK(I9)),I9>=J9,I9<=K9),"적합",IF(ISBLANK(I9),"", "부적합")) -> 부적합 | M9: 79.22 | N9: 33.76 | O9: 113.62
A10: 45919 | B10: HEMA | C10: Blue | D10: NPL-580-2 | E10: =IF(D10="","",IF(B10="Silicone", "SL" & IF(C10="Black","B",IF(C10="White","W",IF(C10="Blue","U",IF(C10="Green","G",IF(C10="Yellow","Y",IF(C10="Red","R",IF(C10="Pink","P",""))))))) & TEXT(A10,"yymmdd") & "01",IF(LEFT(D10,3)="NPL","NPL","PL") & IF(C10="Black","B",IF(C10="White","W",IF(C10="Blue","U",IF(C10="Green","G",IF(C10="Yellow","Y",IF(C10="Red","R",IF(C10="Pink","P",""))))))) & TEXT(A10,"yymmdd") & "01")) -> NPLU25091901 | G10: 외주 | H10: =VLOOKUP(D10,'Spec_Single_H&S'!$B$2:$G$42,6,FALSE) -> PBHBv1.0 | I10: 81690 | J10: =VLOOKUP(D10,'Spec_Single_H&S'!$B$2:$G$42,4,FALSE) -> 53000 | K10: =VLOOKUP(D10,'Spec_Single_H&S'!$B$2:$G$42,5,FALSE) -> 73000 | L10: =IF(AND(NOT(ISBLANK(I10)),I10>=J10,I10<=K10),"적합",IF(ISBLANK(I10),"", "부적합")) -> 부적합 | M10: 11.51 | N10: 7.22 | O10: -27.83
A11: 45923 | B11: HEMA | C11: Blue | D11: PL-580-2(H) | E11: =IF(D11="","",IF(B11="Silicone", "SL" & IF(C11="Black","B",IF(C11="White","W",IF(C11="Blue","U",IF(C11="Green","G",IF(C11="Yellow","Y",IF(C11="Red","R",IF(C11="Pink","P",""))))))) & TEXT(A11,"yymmdd") & "01",IF(LEFT(D11,3)="NPL","NPL","PL") & IF(C11="Black","B",IF(C11="White","W",IF(C11="Blue","U",IF(C11="Green","G",IF(C11="Yellow","Y",IF(C11="Red","R",IF(C11="Pink","P",""))))))) & TEXT(A11,"yymmdd") & "01")) -> PLU25092301 | G11: 외주 | H11: =VLOOKUP(D11,'Spec_Single_H&S'!$B$2:$G$42,6,FALSE) -> PBHAv1.0 | I11: 95910 | J11: =VLOOKUP(D11,'Spec_Single_H&S'!$B$2:$G$42,4,FALSE) -> 53000 | K11: =VLOOKUP(D11,'Spec_Single_H&S'!$B$2:$G$42,5,FALSE) -> 73000 | L11: =IF(AND(NOT(ISBLANK(I11)),I11>=J11,I11<=K11),"적합",IF(ISBLANK(I11),"", "부적합")) -> 부적합 | M11: 9.99 | N11: 6.59 | O11: -24.97
A12: 45925 | B12: HEMA | C12: Blue | D12: PL-580-2(H) | E12: =IF(D12="","",IF(B12="Silicone", "SL" & IF(C12="Black","B",IF(C12="White","W",IF(C12="Blue","U",IF(C12="Green","G",IF(C12="Yellow","Y",IF(C12="Red","R",IF(C12="Pink","P",""))))))) & TEXT(A12,"yymmdd") & "01",IF(LEFT(D12,3)="NPL","NPL","PL") & IF(C12="Black","B",IF(C12="White","W",IF(C12="Blue","U",IF(C12="Green","G",IF(C12="Yellow","Y",IF(C12="Red","R",IF(C12="Pink","P",""))))))) & TEXT(A12,"yymmdd") & "01")) -> PLU25092501 | G12: 외주 | H12: =VLOOKUP(D12,'Spec_Single_H&S'!$B$2:$G$42,6,FALSE) -> PBHAv1.0 | I12: 104000 | J12: =VLOOKUP(D12,'Spec_Single_H&S'!$B$2:$G$42,4,FALSE) -> 53000 | K12: =VLOOKUP(D12,'Spec_Single_H&S'!$B$2:$G$42,5,FALSE) -> 73000 | L12: =IF(AND(NOT(ISBLANK(I12)),I12>=J12,I12<=K12),"적합",IF(ISBLANK(I12),"", "부적합")) -> 부적합 | M12: 12.16 | N12: 6.49 | O12: -22.52
A13: 45930 | B13: HEMA | C13: Blue | D13: PL-550 | E13: =IF(D13="","",IF(B13="Silicone", "SL" & IF(C13="Black","B",IF(C13="White","W",IF(C13="Blue","U",IF(C13="Green","G",IF(C13="Yellow","Y",IF(C13="Red","R",IF(C13="Pink","P",""))))))) & TEXT(A13,"yymmdd") & "01",IF(LEFT(D13,3)="NPL","NPL","PL") & IF(C13="Black","B",IF(C13="White","W",IF(C13="Blue","U",IF(C13="Green","G",IF(C13="Yellow","Y",IF(C13="Red","R",IF(C13="Pink","P",""))))))) & TEXT(A13,"yymmdd") & "01")) -> PLU25093001 | G13: 외주 | H13: =VLOOKUP(D13,'Spec_Single_H&S'!$B$2:$G$42,6,FALSE) -> PBHAv1.0 | I13: 13720 | J13: =VLOOKUP(D13,'Spec_Single_H&S'!$B$2:$G$42,4,FALSE) -> 30000 | K13: =VLOOKUP(D13,'Spec_Single_H&S'!$B$2:$G$42,5,FALSE) -> 40000 | L13: =IF(AND(NOT(ISBLANK(I13)),I13>=J13,I13<=K13),"적합",IF(ISBLANK(I13),"", "부적합")) -> 부적합
A14: 45930 | B14: HEMA | C14: Yellow | D14: NPL-345-3 | E14: =IF(D14="","",IF(B14="Silicone", "SL" & IF(C14="Black","B",IF(C14="White","W",IF(C14="Blue","U",IF(C14="Green","G",IF(C14="Yellow","Y",IF(C14="Red","R",IF(C14="Pink","P",""))))))) & TEXT(A14,"yymmdd") & "01",IF(LEFT(D14,3)="NPL","NPL","PL") & IF(C14="Black","B",IF(C14="White","W",IF(C14="Blue","U",IF(C14="Green","G",IF(C14="Yellow","Y",IF(C14="Red","R",IF(C14="Pink","P",""))))))) & TEXT(A14,"yymmdd") & "01")) -> NPLY25093001 | G14: 외주 | H14: =VLOOKUP(D14,'Spec_Single_H&S'!$B$2:$G$42,6,FALSE) -> PBHBv1.0 | I14: 39200 | J14: =VLOOKUP(D14,'Spec_Single_H&S'!$B$2:$G$42,4,FALSE) -> 20000 | K14: =VLOOKUP(D14,'Spec_Single_H&S'!$B$2:$G$42,5,FALSE) -> 30000 | L14: =IF(AND(NOT(ISBLANK(I14)),I14>=J14,I14<=K14),"적합",IF(ISBLANK(I14),"", "부적합")) -> 부적합 | M14: 80.69 | N14: 31.24 | O14: 116.42
A15: 45930 | B15: HEMA | C15: White | D15: NPL-700-2 | E15: =IF(D15="","",IF(B15="Silicone", "SL" & IF(C15="Black","B",IF(C15="White","W",IF(C15="Blue","U",IF(C15="Green","G",IF(C15="Yellow","Y",IF(C15="Red","R",IF(C15="Pink","P",""))))))) & TEXT(A15,"yymmdd") & "01",IF(LEFT(D15,3)="NPL","NPL","PL") & IF(C15="Black","B",IF(C15="White","W",IF(C15="Blue","U",IF(C15="Green","G",IF(C15="Yellow","Y",IF(C15="Red","R",IF(C15="Pink","P",""))))))) & TEXT(A15,"yymmdd") & "01")) -> NPLW25093001 | G15: 외주 | H15: =VLOOKUP(D15,'Spec_Single_H&S'!$B$2:$G$42,6,FALSE) -> PBHBv1.0 | I15: 14300 | J15: =VLOOKUP(D15,'Spec_Single_H&S'!$B$2:$G$42,4,FALSE) -> 14000 | K15: =VLOOKUP(D15,'Spec_Single_H&S'!$B$2:$G$42,5,FALSE) -> 24000 | L15: =IF(AND(NOT(ISBLANK(I15)),I15>=J15,I15<=K15),"적합",IF(ISBLANK(I15),"", "부적합")) -> 적합 | M15: 95.71 | N15: -0.03 | O15: 3.02
A16: 45930 | B16: HEMA | C16: White | D16: NPL-735 | E16: =IF(D16="","",IF(B16="Silicone", "SL" & IF(C16="Black","B",IF(C16="White","W",IF(C16="Blue","U",IF(C16="Green","G",IF(C16="Yellow","Y",IF(C16="Red","R",IF(C16="Pink","P",""))))))) & TEXT(A16,"yymmdd") & "01",IF(LEFT(D16,3)="NPL","NPL","PL") & IF(C16="Black","B",IF(C16="White","W",IF(C16="Blue","U",IF(C16="Green","G",IF(C16="Yellow","Y",IF(C16="Red","R",IF(C16="Pink","P",""))))))) & TEXT(A16,"yymmdd") & "01")) -> NPLW25093001 | G16: 외주 | H16: =VLOOKUP(D16,'Spec_Single_H&S'!$B$2:$G$42,6,FALSE) -> PBHBv1.0 | I16: 18500 | J16: =VLOOKUP(D16,'Spec_Single_H&S'!$B$2:$G$42,4,FALSE) -> 11000 | K16: =VLOOKUP(D16,'Spec_Single_H&S'!$B$2:$G$42,5,FALSE) -> 21000 | L16: =IF(AND(NOT(ISBLANK(I16)),I16>=J16,I16<=K16),"적합",IF(ISBLANK(I16),"", "부적합")) -> 적합 | M16: 94.08 | N16: 0.24 | O16: 2.57
A17: 45952 | B17: HEMA | C17: Blue | D17: PL-580-2 | E17: =IF(D17="","",IF(B17="Silicone", "SL" & IF(C17="Black","B",IF(C17="White","W",IF(C17="Blue","U",IF(C17="Green","G",IF(C17="Yellow","Y",IF(C17="Red","R",IF(C17="Pink","P",""))))))) & TEXT(A17,"yymmdd") & "01",IF(LEFT(D17,3)="NPL","NPL","PL") & IF(C17="Black","B",IF(C17="White","W",IF(C17="Blue","U",IF(C17="Green","G",IF(C17="Yellow","Y",IF(C17="Red","R",IF(C17="Pink","P",""))))))) & TEXT(A17,"yymmdd") & "01")) -> PLU25102201 | G17: 외주 | H17: =VLOOKUP(D17,'Spec_Single_H&S'!$B$2:$G$42,6,FALSE) -> PBHAv1.0 | I17: 74530 | J17: =VLOOKUP(D17,'Spec_Single_H&S'!$B$2:$G$42,4,FALSE) -> 53000 | K17: =VLOOKUP(D17,'Spec_Single_H&S'!$B$2:$G$42,5,FALSE) -> 73000 | L17: =IF(AND(NOT(ISBLANK(I17)),I17>=J17,I17<=K17),"적합",IF(ISBLANK(I17),"", "부적합")) -> 부적합
A18: 45953 | B18: HEMA | C18: Black | D18: PL-835-1 | E18: =IF(D18="","",IF(B18="Silicone", "SL" & IF(C18="Black","B",IF(C18="White","W",IF(C18="Blue","U",IF(C18="Green","G",IF(C18="Yellow","Y",IF(C18="Red","R",IF(C18="Pink","P",""))))))) & TEXT(A18,"yymmdd") & "01",IF(LEFT(D18,3)="NPL","NPL","PL") & IF(C18="Black","B",IF(C18="White","W",IF(C18="Blue","U",IF(C18="Green","G",IF(C18="Yellow","Y",IF(C18="Red","R",IF(C18="Pink","P",""))))))) & TEXT(A18,"yymmdd") & "01")) -> PLB25102301 | F18: PCB20250930-01 | G18: 외주 | H18: =VLOOKUP(D18,'Spec_Single_H&S'!$B$2:$G$42,6,FALSE) -> PBHAv1.0 | I18: 55150 | J18: =VLOOKUP(D18,'Spec_Single_H&S'!$B$2:$G$42,4,FALSE) -> 60000 | K18: =VLOOKUP(D18,'Spec_Single_H&S'!$B$2:$G$42,5,FALSE) -> 90000 | L18: =IF(AND(NOT(ISBLANK(I18)),I18>=J18,I18<=K18),"적합",IF(ISBLANK(I18),"", "부적합")) -> 부적합 | M18: 12.86 | N18: 0.31 | O18: 0.61
A19: 45953 | B19: HEMA | C19: White | D19: PL-700-2 | E19: =IF(D19="","",IF(B19="Silicone", "SL" & IF(C19="Black","B",IF(C19="White","W",IF(C19="Blue","U",IF(C19="Green","G",IF(C19="Yellow","Y",IF(C19="Red","R",IF(C19="Pink","P",""))))))) & TEXT(A19,"yymmdd") & "01",IF(LEFT(D19,3)="NPL","NPL","PL") & IF(C19="Black","B",IF(C19="White","W",IF(C19="Blue","U",IF(C19="Green","G",IF(C19="Yellow","Y",IF(C19="Red","R",IF(C19="Pink","P",""))))))) & TEXT(A19,"yymmdd") & "01")) -> PLW25102301 | F19: PCB20250930-02 | G19: 외주 | H19: =VLOOKUP(D19,'Spec_Single_H&S'!$B$2:$G$42,6,FALSE) -> PBHAv1.0 | I19: 23490 | J19: =VLOOKUP(D19,'Spec_Single_H&S'!$B$2:$G$42,4,FALSE) -> 14000 | K19: =VLOOKUP(D19,'Spec_Single_H&S'!$B$2:$G$42,5,FALSE) -> 24000 | L19: =IF(AND(NOT(ISBLANK(I19)),I19>=J19,I19<=K19),"적합",IF(ISBLANK(I19),"", "부적합")) -> 적합 | M19: 95.68 | N19: 0.15 | O19: 1.99
A20: 45953 | B20: HEMA | C20: White | D20: PL-735 | E20: =IF(D20="","",IF(B20="Silicone", "SL" & IF(C20="Black","B",IF(C20="White","W",IF(C20="Blue","U",IF(C20="Green","G",IF(C20="Yellow","Y",IF(C20="Red","R",IF(C20="Pink","P",""))))))) & TEXT(A20,"yymmdd") & "01",IF(LEFT(D20,3)="NPL","NPL","PL") & IF(C20="Black","B",IF(C20="White","W",IF(C20="Blue","U",IF(C20="Green","G",IF(C20="Yellow","Y",IF(C20="Red","R",IF(C20="Pink","P",""))))))) & TEXT(A20,"yymmdd") & "01")) -> PLW25102301 | F20: PCB20250930-02 | G20: 외주 | H20: =VLOOKUP(D20,'Spec_Single_H&S'!$B$2:$G$42,6,FALSE) -> PBHAv1.0 | I20: 60480 | J20: =VLOOKUP(D20,'Spec_Single_H&S'!$B$2:$G$42,4,FALSE) -> 11000 | K20: =VLOOKUP(D20,'Spec_Single_H&S'!$B$2:$G$42,5,FALSE) -> 21000 | L20: =IF(AND(NOT(ISBLANK(I20)),I20>=J20,I20<=K20),"적합",IF(ISBLANK(I20),"", "부적합")) -> 부적합 | M20: 93.95 | N20: 0.31 | O20: 3.31
A21: 45953 | B21: HEMA | C21: Red | D21: PL-150-2 | E21: =IF(D21="","",IF(B21="Silicone", "SL" & IF(C21="Black","B",IF(C21="White","W",IF(C21="Blue","U",IF(C21="Green","G",IF(C21="Yellow","Y",IF(C21="Red","R",IF(C21="Pink","P",""))))))) & TEXT(A21,"yymmdd") & "01",IF(LEFT(D21,3)="NPL","NPL","PL") & IF(C21="Black","B",IF(C21="White","W",IF(C21="Blue","U",IF(C21="Green","G",IF(C21="Yellow","Y",IF(C21="Red","R",IF(C21="Pink","P",""))))))) & TEXT(A21,"yymmdd") & "01")) -> PLR25102301 | F21: PCB20250930-02 | G21: 외주 | H21: =VLOOKUP(D21,'Spec_Single_H&S'!$B$2:$G$42,6,FALSE) -> PBHAv1.0 | I21: 24880 | J21: =VLOOKUP(D21,'Spec_Single_H&S'!$B$2:$G$42,4,FALSE) -> 6000 | K21: =VLOOKUP(D21,'Spec_Single_H&S'!$B$2:$G$42,5,FALSE) -> 16000 | L21: =IF(AND(NOT(ISBLANK(I21)),I21>=J21,I21<=K21),"적합",IF(ISBLANK(I21),"", "부적합")) -> 부적합 | M21: 39.38 | N21: 54.53 | O21: 48.23
A22: 45953 | B22: HEMA | C22: Yellow | D22: PL-345-2 | E22: =IF(D22="","",IF(B22="Silicone", "SL" & IF(C22="Black","B",IF(C22="White","W",IF(C22="Blue","U",IF(C22="Green","G",IF(C22="Yellow","Y",IF(C22="Red","R",IF(C22="Pink","P",""))))))) & TEXT(A22,"yymmdd") & "01",IF(LEFT(D22,3)="NPL","NPL","PL") & IF(C22="Black","B",IF(C22="White","W",IF(C22="Blue","U",IF(C22="Green","G",IF(C22="Yellow","Y",IF(C22="Red","R",IF(C22="Pink","P",""))))))) & TEXT(A22,"yymmdd") & "01")) -> PLY25102301 | F22: PCB20250930-02 | G22: 외주 | H22: =VLOOKUP(D22,'Spec_Single_H&S'!$B$2:$G$42,6,FALSE) -> PBHAv1.0 | I22: 43510 | J22: =VLOOKUP(D22,'Spec_Single_H&S'!$B$2:$G$42,4,FALSE) -> 20000 | K22: =VLOOKUP(D22,'Spec_Single_H&S'!$B$2:$G$42,5,FALSE) -> 30000 | L22: =IF(AND(NOT(ISBLANK(I22)),I22>=J22,I22<=K22),"적합",IF(ISBLANK(I22),"", "부적합")) -> 부적합 | M22: 80.14 | N22: 32.21 | O22: 114.44
A23: 45958 | B23: HEMA | C23: Yellow | D23: PL-345-3 | E23: =IF(D23="","",IF(B23="Silicone", "SL" & IF(C23="Black","B",IF(C23="White","W",IF(C23="Blue","U",IF(C23="Green","G",IF(C23="Yellow","Y",IF(C23="Red","R",IF(C23="Pink","P",""))))))) & TEXT(A23,"yymmdd") & "01",IF(LEFT(D23,3)="NPL","NPL","PL") & IF(C23="Black","B",IF(C23="White","W",IF(C23="Blue","U",IF(C23="Green","G",IF(C23="Yellow","Y",IF(C23="Red","R",IF(C23="Pink","P",""))))))) & TEXT(A23,"yymmdd") & "01")) -> PLY25102801 | F23: PCB20251016-01 | G23: 외주 | H23: =VLOOKUP(D23,'Spec_Single_H&S'!$B$2:$G$42,6,FALSE) -> PBHAv1.0 | I23: 27660 | J23: =VLOOKUP(D23,'Spec_Single_H&S'!$B$2:$G$42,4,FALSE) -> 20000 | K23: =VLOOKUP(D23,'Spec_Single_H&S'!$B$2:$G$42,5,FALSE) -> 30000 | L23: =IF(AND(NOT(ISBLANK(I23)),I23>=J23,I23<=K23),"적합",IF(ISBLANK(I23),"", "부적합")) -> 적합 | M23: 81.62 | N23: 29.61 | O23: 106.27
A24: 45958 | B24: HEMA | C24: Yellow | D24: PL-345-2 | E24: =IF(D24="","",IF(B24="Silicone", "SL" & IF(C24="Black","B",IF(C24="White","W",IF(C24="Blue","U",IF(C24="Green","G",IF(C24="Yellow","Y",IF(C24="Red","R",IF(C24="Pink","P",""))))))) & TEXT(A24,"yymmdd") & "01",IF(LEFT(D24,3)="NPL","NPL","PL") & IF(C24="Black","B",IF(C24="White","W",IF(C24="Blue","U",IF(C24="Green","G",IF(C24="Yellow","Y",IF(C24="Red","R",IF(C24="Pink","P",""))))))) & TEXT(A24,"yymmdd") & "01")) -> PLY25102801 | F24: PCB20251016-01 | G24: 외주 | H24: =VLOOKUP(D24,'Spec_Single_H&S'!$B$2:$G$42,6,FALSE) -> PBHAv1.0 | I24: 69710 | J24: =VLOOKUP(D24,'Spec_Single_H&S'!$B$2:$G$42,4,FALSE) -> 20000 | K24: =VLOOKUP(D24,'Spec_Single_H&S'!$B$2:$G$42,5,FALSE) -> 30000 | L24: =IF(AND(NOT(ISBLANK(I24)),I24>=J24,I24<=K24),"적합",IF(ISBLANK(I24),"", "부적합")) -> 부적합 | M24: 80.14 | N24: 32.21 | O24: 114.44
A25: 45958 | B25: HEMA | C25: Red | D25: PL-150-2 | E25: =IF(D25="","",IF(B25="Silicone", "SL" & IF(C25="Black","B",IF(C25="White","W",IF(C25="Blue","U",IF(C25="Green","G",IF(C25="Yellow","Y",IF(C25="Red","R",IF(C25="Pink","P",""))))))) & TEXT(A25,"yymmdd") & "01",IF(LEFT(D25,3)="NPL","NPL","PL") & IF(C25="Black","B",IF(C25="White","W",IF(C25="Blue","U",IF(C25="Green","G",IF(C25="Yellow","Y",IF(C25="Red","R",IF(C25="Pink","P",""))))))) & TEXT(A25,"yymmdd") & "01")) -> PLR25102801 | F25: PCB20250930-02 | G25: 외주 | H25: =VLOOKUP(D25,'Spec_Single_H&S'!$B$2:$G$42,6,FALSE) -> PBHAv1.0 | I25: 22000 | J25: =VLOOKUP(D25,'Spec_Single_H&S'!$B$2:$G$42,4,FALSE) -> 6000 | K25: =VLOOKUP(D25,'Spec_Single_H&S'!$B$2:$G$42,5,FALSE) -> 16000 | L25: =IF(AND(NOT(ISBLANK(I25)),I25>=J25,I25<=K25),"적합",IF(ISBLANK(I25),"", "부적합")) -> 부적합 | M25: 42.06 | N25: 59.54 | O25: 51.51
A26: 45958 | B26: HEMA | C26: Pink | D26: PL-135 | E26: =IF(D26="","",IF(B26="Silicone", "SL" & IF(C26="Black","B",IF(C26="White","W",IF(C26="Blue","U",IF(C26="Green","G",IF(C26="Yellow","Y",IF(C26="Red","R",IF(C26="Pink","P",""))))))) & TEXT(A26,"yymmdd") & "01",IF(LEFT(D26,3)="NPL","NPL","PL") & IF(C26="Black","B",IF(C26="White","W",IF(C26="Blue","U",IF(C26="Green","G",IF(C26="Yellow","Y",IF(C26="Red","R",IF(C26="Pink","P",""))))))) & TEXT(A26,"yymmdd") & "01")) -> PLP25102801 | G26: 외주 | H26: =VLOOKUP(D26,'Spec_Single_H&S'!$B$2:$G$42,6,FALSE) -> PBHAv1.0 | J26: =VLOOKUP(D26,'Spec_Single_H&S'!$B$2:$G$42,4,FALSE) -> 7000 | K26: =VLOOKUP(D26,'Spec_Single_H&S'!$B$2:$G$42,5,FALSE) -> 17000 | L26: =IF(AND(NOT(ISBLANK(I26)),I26>=J26,I26<=K26),"적합",IF(ISBLANK(I26),"", "부적합"))
A27: 45958 | B27: HEMA | C27: Green | D27: PL-435 | E27: =IF(D27="","",IF(B27="Silicone", "SL" & IF(C27="Black","B",IF(C27="White","W",IF(C27="Blue","U",IF(C27="Green","G",IF(C27="Yellow","Y",IF(C27="Red","R",IF(C27="Pink","P",""))))))) & TEXT(A27,"yymmdd") & "01",IF(LEFT(D27,3)="NPL","NPL","PL") & IF(C27="Black","B",IF(C27="White","W",IF(C27="Blue","U",IF(C27="Green","G",IF(C27="Yellow","Y",IF(C27="Red","R",IF(C27="Pink","P",""))))))) & TEXT(A27,"yymmdd") & "01")) -> PLG25102801 | G27: 외주 | H27: =VLOOKUP(D27,'Spec_Single_H&S'!$B$2:$G$42,6,FALSE) -> PBHAv1.0 | J27: =VLOOKUP(D27,'Spec_Single_H&S'!$B$2:$G$42,4,FALSE) -> 4000 | K27: =VLOOKUP(D27,'Spec_Single_H&S'!$B$2:$G$42,5,FALSE) -> 10000 | L27: =IF(AND(NOT(ISBLANK(I27)),I27>=J27,I27<=K27),"적합",IF(ISBLANK(I27),"", "부적합"))
A28: 45973 | B28: HEMA | C28: Yellow | D28: PL-345-2 | E28: =IF(D28="","",IF(B28="Silicone", "SL" & IF(C28="Black","B",IF(C28="White","W",IF(C28="Blue","U",IF(C28="Green","G",IF(C28="Yellow","Y",IF(C28="Red","R",IF(C28="Pink","P",""))))))) & TEXT(A28,"yymmdd") & "01",IF(LEFT(D28,3)="NPL","NPL","PL") & IF(C28="Black","B",IF(C28="White","W",IF(C28="Blue","U",IF(C28="Green","G",IF(C28="Yellow","Y",IF(C28="Red","R",IF(C28="Pink","P",""))))))) & TEXT(A28,"yymmdd") & "01")) -> PLY25111201 | F28: PCB20251027-02 | G28: 외주 | H28: =VLOOKUP(D28,'Spec_Single_H&S'!$B$2:$G$42,6,FALSE) -> PBHAv1.0 | I28: 35310 | J28: =VLOOKUP(D28,'Spec_Single_H&S'!$B$2:$G$42,4,FALSE) -> 20000 | K28: =VLOOKUP(D28,'Spec_Single_H&S'!$B$2:$G$42,5,FALSE) -> 30000 | L28: =IF(AND(NOT(ISBLANK(I28)),I28>=J28,I28<=K28),"적합",IF(ISBLANK(I28),"", "부적합")) -> 부적합 | M28: 78.5 | N28: 35.3 | O28: 112.9
A29: 45973 | B29: HEMA | C29: Black | D29: PL-835-1(H) | E29: =IF(D29="","",IF(B29="Silicone", "SL" & IF(C29="Black","B",IF(C29="White","W",IF(C29="Blue","U",IF(C29="Green","G",IF(C29="Yellow","Y",IF(C29="Red","R",IF(C29="Pink","P",""))))))) & TEXT(A29,"yymmdd") & "01",IF(LEFT(D29,3)="NPL","NPL","PL") & IF(C29="Black","B",IF(C29="White","W",IF(C29="Blue","U",IF(C29="Green","G",IF(C29="Yellow","Y",IF(C29="Red","R",IF(C29="Pink","P",""))))))) & TEXT(A29,"yymmdd") & "01")) -> PLB25111201 | F29: PCB20251028-01 | G29: 외주 | H29: =VLOOKUP(D29,'Spec_Single_H&S'!$B$2:$G$42,6,FALSE) -> PBHAv1.0 | I29: 56980 | J29: =VLOOKUP(D29,'Spec_Single_H&S'!$B$2:$G$42,4,FALSE) -> 60000 | K29: =VLOOKUP(D29,'Spec_Single_H&S'!$B$2:$G$42,5,FALSE) -> 90000 | L29: =IF(AND(NOT(ISBLANK(I29)),I29>=J29,I29<=K29),"적합",IF(ISBLANK(I29),"", "부적합")) -> 부적합 | M29: 9.8 | N29: -0.34 | O29: -1.12
A30: 45974 | B30: HEMA | C30: Black | D30: PL-835-1 | E30: =IF(D30="","",IF(B30="Silicone", "SL" & IF(C30="Black","B",IF(C30="White","W",IF(C30="Blue","U",IF(C30="Green","G",IF(C30="Yellow","Y",IF(C30="Red","R",IF(C30="Pink","P",""))))))) & TEXT(A30,"yymmdd") & "01",IF(LEFT(D30,3)="NPL","NPL","PL") & IF(C30="Black","B",IF(C30="White","W",IF(C30="Blue","U",IF(C30="Green","G",IF(C30="Yellow","Y",IF(C30="Red","R",IF(C30="Pink","P",""))))))) & TEXT(A30,"yymmdd") & "01")) -> PLB25111301 | F30: PCB20251028-02 | G30: 외주 | H30: =VLOOKUP(D30,'Spec_Single_H&S'!$B$2:$G$42,6,FALSE) -> PBHAv1.0 | I30: 46860 | J30: =VLOOKUP(D30,'Spec_Single_H&S'!$B$2:$G$42,4,FALSE) -> 60000 | K30: =VLOOKUP(D30,'Spec_Single_H&S'!$B$2:$G$42,5,FALSE) -> 90000 | L30: =IF(AND(NOT(ISBLANK(I30)),I30>=J30,I30<=K30),"적합",IF(ISBLANK(I30),"", "부적합")) -> 부적합 | M30: 9.55 | N30: -0.14 | O30: -0.73
A31: 45974 | B31: HEMA | C31: Red | D31: PL-150-2 | E31: =IF(D31="","",IF(B31="Silicone", "SL" & IF(C31="Black","B",IF(C31="White","W",IF(C31="Blue","U",IF(C31="Green","G",IF(C31="Yellow","Y",IF(C31="Red","R",IF(C31="Pink","P",""))))))) & TEXT(A31,"yymmdd") & "01",IF(LEFT(D31,3)="NPL","NPL","PL") & IF(C31="Black","B",IF(C31="White","W",IF(C31="Blue","U",IF(C31="Green","G",IF(C31="Yellow","Y",IF(C31="Red","R",IF(C31="Pink","P",""))))))) & TEXT(A31,"yymmdd") & "01")) -> PLR25111301 | F31: PCB20251029-01 | G31: 외주 | H31: =VLOOKUP(D31,'Spec_Single_H&S'!$B$2:$G$42,6,FALSE) -> PBHAv1.0 | I31: 12240 | J31: =VLOOKUP(D31,'Spec_Single_H&S'!$B$2:$G$42,4,FALSE) -> 6000 | K31: =VLOOKUP(D31,'Spec_Single_H&S'!$B$2:$G$42,5,FALSE) -> 16000 | L31: =IF(AND(NOT(ISBLANK(I31)),I31>=J31,I31<=K31),"적합",IF(ISBLANK(I31),"", "부적합")) -> 적합 | M31: 40.23 | N31: 56.99 | O31: 50.33
A32: 45980 | B32: Silicone | C32: Yellow | D32: SL-345 | E32: =IF(D32="","",IF(B32="Silicone", "SL" & IF(C32="Black","B",IF(C32="White","W",IF(C32="Blue","U",IF(C32="Green","G",IF(C32="Yellow","Y",IF(C32="Red","R",IF(C32="Pink","P",""))))))) & TEXT(A32,"yymmdd") & "01",IF(LEFT(D32,3)="NPL","NPL","PL") & IF(C32="Black","B",IF(C32="White","W",IF(C32="Blue","U",IF(C32="Green","G",IF(C32="Yellow","Y",IF(C32="Red","R",IF(C32="Pink","P",""))))))) & TEXT(A32,"yymmdd") & "01")) -> SLY25111901 | G32: 외주 | H32: =VLOOKUP(D32,'Spec_Single_H&S'!$B$2:$G$42,6,FALSE) -> SBCT | I32: 67660 | J32: =VLOOKUP(D32,'Spec_Single_H&S'!$B$2:$G$42,4,FALSE) -> 11000 | K32: =VLOOKUP(D32,'Spec_Single_H&S'!$B$2:$G$42,5,FALSE) -> 15000 | L32: =IF(AND(NOT(ISBLANK(I32)),I32>=J32,I32<=K32),"적합",IF(ISBLANK(I32),"", "부적합")) -> 부적합 | M32: 82.741 | N32: 30.182 | O32: 121.74
A33: 45980 | B33: Silicone | C33: Black | D33: SL-850 | E33: =IF(D33="","",IF(B33="Silicone", "SL" & IF(C33="Black","B",IF(C33="White","W",IF(C33="Blue","U",IF(C33="Green","G",IF(C33="Yellow","Y",IF(C33="Red","R",IF(C33="Pink","P",""))))))) & TEXT(A33,"yymmdd") & "01",IF(LEFT(D33,3)="NPL","NPL","PL") & IF(C33="Black","B",IF(C33="White","W",IF(C33="Blue","U",IF(C33="Green","G",IF(C33="Yellow","Y",IF(C33="Red","R",IF(C33="Pink","P",""))))))) & TEXT(A33,"yymmdd") & "01")) -> SLB25111901 | G33: 외주 | H33: =VLOOKUP(D33,'Spec_Single_H&S'!$B$2:$G$42,6,FALSE) -> SBCT | I33: 139400 | J33: =VLOOKUP(D33,'Spec_Single_H&S'!$B$2:$G$42,4,FALSE) -> 100000 | K33: =VLOOKUP(D33,'Spec_Single_H&S'!$B$2:$G$42,5,FALSE) -> 140000 | L33: =IF(AND(NOT(ISBLANK(I33)),I33>=J33,I33<=K33),"적합",IF(ISBLANK(I33),"", "부적합")) -> 적합 | M33: 24.737 | N33: 0.4998 | O33: 1.4827
A34: 45980 | B34: Silicone | C34: Red | D34: SL-150 | E34: =IF(D34="","",IF(B34="Silicone", "SL" & IF(C34="Black","B",IF(C34="White","W",IF(C34="Blue","U",IF(C34="Green","G",IF(C34="Yellow","Y",IF(C34="Red","R",IF(C34="Pink","P",""))))))) & TEXT(A34,"yymmdd") & "01",IF(LEFT(D34,3)="NPL","NPL","PL") & IF(C34="Black","B",IF(C34="White","W",IF(C34="Blue","U",IF(C34="Green","G",IF(C34="Yellow","Y",IF(C34="Red","R",IF(C34="Pink","P",""))))))) & TEXT(A34,"yymmdd") & "01")) -> SLR25111901 | G34: 외주 | H34: =VLOOKUP(D34,'Spec_Single_H&S'!$B$2:$G$42,6,FALSE) -> SBCT | I34: 25070 | J34: =VLOOKUP(D34,'Spec_Single_H&S'!$B$2:$G$42,4,FALSE) -> 31000 | K34: =VLOOKUP(D34,'Spec_Single_H&S'!$B$2:$G$42,5,FALSE) -> 41000 | L34: =IF(AND(NOT(ISBLANK(I34)),I34>=J34,I34<=K34),"적합",IF(ISBLANK(I34),"", "부적합")) -> 부적합 | M34: 41.418 | N34: 58.896 | O34: 54.832
A35: 45980 | B35: Silicone | C35: White | D35: SL-700-1 | E35: =IF(D35="","",IF(B35="Silicone", "SL" & IF(C35="Black","B",IF(C35="White","W",IF(C35="Blue","U",IF(C35="Green","G",IF(C35="Yellow","Y",IF(C35="Red","R",IF(C35="Pink","P",""))))))) & TEXT(A35,"yymmdd") & "01",IF(LEFT(D35,3)="NPL","NPL","PL") & IF(C35="Black","B",IF(C35="White","W",IF(C35="Blue","U",IF(C35="Green","G",IF(C35="Yellow","Y",IF(C35="Red","R",IF(C35="Pink","P",""))))))) & TEXT(A35,"yymmdd") & "01")) -> SLW25111901 | G35: 외주 | H35: =VLOOKUP(D35,'Spec_Single_H&S'!$B$2:$G$42,6,FALSE) -> SBCT | I35: 41140 | J35: =VLOOKUP(D35,'Spec_Single_H&S'!$B$2:$G$42,4,FALSE) -> 40000 | K35: =VLOOKUP(D35,'Spec_Single_H&S'!$B$2:$G$42,5,FALSE) -> 60000 | L35: =IF(AND(NOT(ISBLANK(I35)),I35>=J35,I35<=K35),"적합",IF(ISBLANK(I35),"", "부적합")) -> 적합 | M35: 97.067 | N35: 0.1819 | O35: 1.7144
A36: 45980 | B36: HEMA | C36: White | D36: PL-700-2 | E36: =IF(D36="","",IF(B36="Silicone", "SL" & IF(C36="Black","B",IF(C36="White","W",IF(C36="Blue","U",IF(C36="Green","G",IF(C36="Yellow","Y",IF(C36="Red","R",IF(C36="Pink","P",""))))))) & TEXT(A36,"yymmdd") & "01",IF(LEFT(D36,3)="NPL","NPL","PL") & IF(C36="Black","B",IF(C36="White","W",IF(C36="Blue","U",IF(C36="Green","G",IF(C36="Yellow","Y",IF(C36="Red","R",IF(C36="Pink","P",""))))))) & TEXT(A36,"yymmdd") & "01")) -> PLW25111901 | F36: PCB20251030-02 | G36: 외주 | H36: =VLOOKUP(D36,'Spec_Single_H&S'!$B$2:$G$42,6,FALSE) -> PBHAv1.0 | I36: 19040 | J36: =VLOOKUP(D36,'Spec_Single_H&S'!$B$2:$G$42,4,FALSE) -> 14000 | K36: =VLOOKUP(D36,'Spec_Single_H&S'!$B$2:$G$42,5,FALSE) -> 24000 | L36: =IF(AND(NOT(ISBLANK(I36)),I36>=J36,I36<=K36),"적합",IF(ISBLANK(I36),"", "부적합")) -> 적합 | M36: 95.768 | N36: 0.2076 | O36: 1.8724
